Workbook

Sheet Source
A1: Source and workbook assumptions
A3: Field | B3: Value | C3: Notes | D3: URL
A4: Topic | B4: Post-COVID Reshaping of Tourism Seasonality in Asia and the Pacific
A5: Geography | B5: Asia and the Pacific | C5: UN Tourism regional aggregate
A6: Indicator | B6: International tourist arrivals, monthly volumes | C6: Million arrivals
A7: Observation period | B7: 2019-01 to 2024-03 | C7: 2024 contains January-March only
A8: Complete years used in main formulas | B8: 2023 | C8: Full monthly years: 2019-2023
A9: Baseline year | B9: 2019 | C9: Used for monthly recovery index
A10: Outlier threshold | B10: 2 | C10: Absolute residual z-score threshold
A11: Data type | B11: Digitized from official UN Tourism chart; annual-adjusted | C11: Prepared monthly values
A12: Primary source | B12: UN Tourism Data Dashboard | C12: Monthly and annual tourism data | D12: https://www.untourism.int/tourism-data/un-tourism-tourism-dashboard
A13: Statistical source | B13: UN Tourism World Tourism Barometer and Statistical Annex | C13: Chart A-6 and table A-14 | D13: https://www.untourism.int/tourism-data

Sheet Data
A1: t | B1: Date | C1: Year | D1: Month | E1: Month name | F1: Region | G1: Arrivals, mln | H1: ln(arrivals) | I1: Monthly change | J1: YoY change | K1: MA 3 | L1: MA 6 | M1: MA 12 trailing | N1: Trend-cycle MA 12 | O1: Index vs 2019 same month | P1: Seasonal factor | Q1: Deseasonalized | R1: Linear trend | S1: Residual | T1: |Residual| | U1: Residual z-score | V1: Outlier flag | W1: Seasonal difference 12m | X1: Phase | Y1: Absolute percentage error
A2: 1 | B2: 43466 | C2: =YEAR(B2) -> 2019 | D2: =MONTH(B2) -> 1 | E2: =TEXT(B2,"mmm") -> Jan | F2: Asia and the Pacific | G2: 30.872 | H2: =IFERROR(LN(G2),"") -> 3.4298496 | I2: =IF(A2=1,"",G2-G1) | J2: =IFERROR(G2/INDEX($G:$G,MATCH(DATE(C2-1,D2,1),$B:$B,0))-1,"") | K2: ="" | L2: ="" | M2: ="" | N2: ="" | O2: =IFERROR(G2/G2,"") -> 1 | P2: =AVERAGEIFS($G:$G,$D:$D,D2,$C:$C,"<="&Source!$B$8)-AVERAGEIFS($G:$G,$C:$C,"<="&Source!$B$8) -> 2.6040833 | Q2: =G2-P2 -> 28.267917 | R2: =INTERCEPT($G$2:$G$61,$A$2:$A$61)+SLOPE($G$2:$G$61,$A$2:$A$61)*A2 -> 17.138667 | S2: =G2-R2 -> 13.733333 | T2: =ABS(S2) -> 13.733333 | U2: =IFERROR((S2-AVERAGE($S$2:$S$61))/stdev.s($S$2:$S$61),"") -> 1.2251313 | V2: =IF(ABS(U2)>=Source!$B$10,"Anomaly","") | W2: =IF(A2<=12,"",G2-INDEX($G:$G,ROW()-12)) | X2: =IF(C2=2019,"Baseline",IF(C2<=2021,"COVID shock",IF(C2=2022,"Reopening","Recovery"))) -> Baseline | Y2: =IFERROR(ABS(S2/G2),"") -> 0.44484754
A3: 2 | B3: 43497 | C3: =YEAR(B3) -> 2019 | D3: =MONTH(B3) -> 2 | E3: =TEXT(B3,"mmm") -> Feb | F3: Asia and the Pacific | G3: 30.366 | H3: =IFERROR(LN(G3),"") -> 3.4133236 | I3: =IF(A3=1,"",G3-G2) -> -0.506 | J3: =IFERROR(G3/INDEX($G:$G,MATCH(DATE(C3-1,D3,1),$B:$B,0))-1,"") | K3: ="" | L3: ="" | M3: ="" | N3: ="" | O3: =IFERROR(G3/G3,"") -> 1 | P3: =AVERAGEIFS($G:$G,$D:$D,D3,$C:$C,"<="&Source!$B$8)-AVERAGEIFS($G:$G,$C:$C,"<="&Source!$B$8) -> 0.25428333 | Q3: =G3-P3 -> 30.111717 | R3: =INTERCEPT($G$2:$G$61,$A$2:$A$61)+SLOPE($G$2:$G$61,$A$2:$A$61)*A3 -> 16.997712 | S3: =G3-R3 -> 13.368288 | T3: =ABS(S3) -> 13.368288 | U3: =IFERROR((S3-AVERAGE($S$2:$S$61))/stdev.s($S$2:$S$61),"") -> 1.1925661 | V3: =IF(ABS(U3)>=Source!$B$10,"Anomaly","") | W3: =IF(A3<=12,"",G3-INDEX($G:$G,ROW()-12)) | X3: =IF(C3=2019,"Baseline",IF(C3<=2021,"COVID shock",IF(C3=2022,"Reopening","Recovery"))) -> Baseline | Y3: =IFERROR(ABS(S3/G3),"") -> 0.44023867
A4: 3 | B4: 43525 | C4: =YEAR(B4) -> 2019 | D4: =MONTH(B4) -> 3 | E4: =TEXT(B4,"mmm") -> Mar | F4: Asia and the Pacific | G4: 31.985 | H4: =IFERROR(LN(G4),"") -> 3.465267 | I4: =IF(A4=1,"",G4-G3) -> 1.619 | J4: =IFERROR(G4/INDEX($G:$G,MATCH(DATE(C4-1,D4,1),$B:$B,0))-1,"") | K4: =AVERAGE(G2:G4) -> 31.074333 | L4: ="" | M4: ="" | N4: ="" | O4: =IFERROR(G4/G4,"") -> 1 | P4: =AVERAGEIFS($G:$G,$D:$D,D4,$C:$C,"<="&Source!$B$8)-AVERAGEIFS($G:$G,$C:$C,"<="&Source!$B$8) -> -1.3653167 | Q4: =G4-P4 -> 33.350317 | R4: =INTERCEPT($G$2:$G$61,$A$2:$A$61)+SLOPE($G$2:$G$61,$A$2:$A$61)*A4 -> 16.856758 | S4: =G4-R4 -> 15.128242 | T4: =ABS(S4) -> 15.128242 | U4: =IFERROR((S4-AVERAGE($S$2:$S$61))/stdev.s($S$2:$S$61),"") -> 1.3495692 | V4: =IF(ABS(U4)>=Source!$B$10,"Anomaly","") | W4: =IF(A4<=12,"",G4-INDEX($G:$G,ROW()-12)) | X4: =IF(C4=2019,"Baseline",IF(C4<=2021,"COVID shock",IF(C4=2022,"Reopening","Recovery"))) -> Baseline | Y4: =IFERROR(ABS(S4/G4),"") -> 0.47297927
A5: 4 | B5: 43556 | C5: =YEAR(B5) -> 2019 | D5: =MONTH(B5) -> 4 | E5: =TEXT(B5,"mmm") -> Apr | F5: Asia and the Pacific | G5: 31.581 | H5: =IFERROR(LN(G5),"") -> 3.4525557 | I5: =IF(A5=1,"",G5-G4) -> -0.404 | J5: =IFERROR(G5/INDEX($G:$G,MATCH(DATE(C5-1,D5,1),$B:$B,0))-1,"") | K5: =AVERAGE(G3:G5) -> 31.310667 | L5: ="" | M5: ="" | N5: ="" | O5: =IFERROR(G5/G5,"") -> 1 | P5: =AVERAGEIFS($G:$G,$D:$D,D5,$C:$C,"<="&Source!$B$8)-AVERAGEIFS($G:$G,$C:$C,"<="&Source!$B$8) -> -1.5993167 | Q5: =G5-P5 -> 33.180317 | R5: =INTERCEPT($G$2:$G$61,$A$2:$A$61)+SLOPE($G$2:$G$61,$A$2:$A$61)*A5 -> 16.715804 | S5: =G5-R5 -> 14.865196 | T5: =ABS(S5) -> 14.865196 | U5: =IFERROR((S5-AVERAGE($S$2:$S$61))/stdev.s($S$2:$S$61),"") -> 1.3261032 | V5: =IF(ABS(U5)>=Source!$B$10,"Anomaly","") | W5: =IF(A5<=12,"",G5-INDEX($G:$G,ROW()-12)) | X5: =IF(C5=2019,"Baseline",IF(C5<=2021,"COVID shock",IF(C5=2022,"Reopening","Recovery"))) -> Baseline | Y5: =IFERROR(ABS(S5/G5),"") -> 0.47070061
A6: 5 | B6: 43586 | C6: =YEAR(B6) -> 2019 | D6: =MONTH(B6) -> 5 | E6: =TEXT(B6,"mmm") -> May | F6: Asia and the Pacific | G6: 29.354 | H6: =IFERROR(LN(G6),"") -> 3.3794288 | I6: =IF(A6=1,"",G6-G5) -> -2.227 | J6: =IFERROR(G6/INDEX($G:$G,MATCH(DATE(C6-1,D6,1),$B:$B,0))-1,"") | K6: =AVERAGE(G4:G6) -> 30.973333 | L6: ="" | M6: ="" | N6: ="" | O6: =IFERROR(G6/G6,"") -> 1 | P6: =AVERAGEIFS($G:$G,$D:$D,D6,$C:$C,"<="&Source!$B$8)-AVERAGEIFS($G:$G,$C:$C,"<="&Source!$B$8) -> -1.7461167 | Q6: =G6-P6 -> 31.100117 | R6: =INTERCEPT($G$2:$G$61,$A$2:$A$61)+SLOPE($G$2:$G$61,$A$2:$A$61)*A6 -> 16.57485 | S6: =G6-R6 -> 12.77915 | T6: =ABS(S6) -> 12.77915 | U6: =IFERROR((S6-AVERAGE($S$2:$S$61))/stdev.s($S$2:$S$61),"") -> 1.14001 | V6: =IF(ABS(U6)>=Source!$B$10,"Anomaly","") | W6: =IF(A6<=12,"",G6-INDEX($G:$G,ROW()-12)) | X6: =IF(C6=2019,"Baseline",IF(C6<=2021,"COVID shock",IF(C6=2022,"Reopening","Recovery"))) -> Baseline | Y6: =IFERROR(ABS(S6/G6),"") -> 0.43534613
A7: 6 | B7: 43617 | C7: =YEAR(B7) -> 2019 | D7: =MONTH(B7) -> 6 | E7: =TEXT(B7,"mmm") -> Jun | F7: Asia and the Pacific | G7: 29.556 | H7: =IFERROR(LN(G7),"") -> 3.3862868 | I7: =IF(A7=1,"",G7-G6) -> 0.202 | J7: =IFERROR(G7/INDEX($G:$G,MATCH(DATE(C7-1,D7,1),$B:$B,0))-1,"") | K7: =AVERAGE(G5:G7) -> 30.163667 | L7: =AVERAGE(G2:G7) -> 30.619 | M7: ="" | N7: ="" | O7: =IFERROR(G7/G7,"") -> 1 | P7: =AVERAGEIFS($G:$G,$D:$D,D7,$C:$C,"<="&Source!$B$8)-AVERAGEIFS($G:$G,$C:$C,"<="&Source!$B$8) -> -1.1057167 | Q7: =G7-P7 -> 30.661717 | R7: =INTERCEPT($G$2:$G$61,$A$2:$A$61)+SLOPE($G$2:$G$61,$A$2:$A$61)*A7 -> 16.433895 | S7: =G7-R7 -> 13.122105 | T7: =ABS(S7) -> 13.122105 | U7: =IFERROR((S7-AVERAGE($S$2:$S$61))/stdev.s($S$2:$S$61),"") -> 1.1706045 | V7: =IF(ABS(U7)>=Source!$B$10,"Anomaly","") | W7: =IF(A7<=12,"",G7-INDEX($G:$G,ROW()-12)) | X7: =IF(C7=2019,"Baseline",IF(C7<=2021,"COVID shock",IF(C7=2022,"Reopening","Recovery"))) -> Baseline | Y7: =IFERROR(ABS(S7/G7),"") -> 0.4439743
A8: 7 | B8: 43647 | C8: =YEAR(B8) -> 2019 | D8: =MONTH(B8) -> 7 | E8: =TEXT(B8,"mmm") -> Jul | F8: Asia and the Pacific | G8: 30.872 | H8: =IFERROR(LN(G8),"") -> 3.4298496 | I8: =IF(A8=1,"",G8-G7) -> 1.316 | J8: =IFERROR(G8/INDEX($G:$G,MATCH(DATE(C8-1,D8,1),$B:$B,0))-1,"") | K8: =AVERAGE(G6:G8) -> 29.927333 | L8: =AVERAGE(G3:G8) -> 30.619 | M8: ="" | N8: =AVERAGE(G3:G14) -> 30.025917 | O8: =IFERROR(G8/G8,"") -> 1 | P8: =AVERAGEIFS($G:$G,$D:$D,D8,$C:$C,"<="&Source!$B$8)-AVERAGEIFS($G:$G,$C:$C,"<="&Source!$B$8) -> 0.12048333 | Q8: =G8-P8 -> 30.751517 | R8: =INTERCEPT($G$2:$G$61,$A$2:$A$61)+SLOPE($G$2:$G$61,$A$2:$A$61)*A8 -> 16.292941 | S8: =G8-R8 -> 14.579059 | T8: =ABS(S8) -> 14.579059 | U8: =IFERROR((S8-AVERAGE($S$2:$S$61))/stdev.s($S$2:$S$61),"") -> 1.3005773 | V8: =IF(ABS(U8)>=Source!$B$10,"Anomaly","") | W8: =IF(A8<=12,"",G8-INDEX($G:$G,ROW()-12)) | X8: =IF(C8=2019,"Baseline",IF(C8<=2021,"COVID shock",IF(C8=2022,"Reopening","Recovery"))) -> Baseline | Y8: =IFERROR(ABS(S8/G8),"") -> 0.47224212
A9: 8 | B9: 43678 | C9: =YEAR(B9) -> 2019 | D9: =MONTH(B9) -> 8 | E9: =TEXT(B9,"mmm") -> Aug | F9: Asia and the Pacific | G9: 30.366 | H9: =IFERROR(LN(G9),"") -> 3.4133236 | I9: =IF(A9=1,"",G9-G8) -> -0.506 | J9: =IFERROR(G9/INDEX($G:$G,MATCH(DATE(C9-1,D9,1),$B:$B,0))-1,"") | K9: =AVERAGE(G7:G9) -> 30.264667 | L9: =AVERAGE(G4:G9) -> 30.619 | M9: ="" | N9: =AVERAGE(G4:G15) -> 28.841833 | O9: =IFERROR(G9/G9,"") -> 1 | P9: =AVERAGEIFS($G:$G,$D:$D,D9,$C:$C,"<="&Source!$B$8)-AVERAGEIFS($G:$G,$C:$C,"<="&Source!$B$8) -> 0.26948333 | Q9: =G9-P9 -> 30.096517 | R9: =INTERCEPT($G$2:$G$61,$A$2:$A$61)+SLOPE($G$2:$G$61,$A$2:$A$61)*A9 -> 16.151987 | S9: =G9-R9 -> 14.214013 | T9: =ABS(S9) -> 14.214013 | U9: =IFERROR((S9-AVERAGE($S$2:$S$61))/stdev.s($S$2:$S$61),"") -> 1.2680121 | V9: =IF(ABS(U9)>=Source!$B$10,"Anomaly","") | W9: =IF(A9<=12,"",G9-INDEX($G:$G,ROW()-12)) | X9: =IF(C9=2019,"Baseline",IF(C9<=2021,"COVID shock",IF(C9=2022,"Reopening","Recovery"))) -> Baseline | Y9: =IFERROR(ABS(S9/G9),"") -> 0.46808974
A10: 9 | B10: 43709 | C10: =YEAR(B10) -> 2019 | D10: =MONTH(B10) -> 9 | E10: =TEXT(B10,"mmm") -> Sep | F10: Asia and the Pacific | G10: 27.127 | H10: =IFERROR(LN(G10),"") -> 3.3005295 | I10: =IF(A10=1,"",G10-G9) -> -3.239 | J10: =IFERROR(G10/INDEX($G:$G,MATCH(DATE(C10-1,D10,1),$B:$B,0))-1,"") | K10: =AVERAGE(G8:G10) -> 29.455 | L10: =AVERAGE(G5:G10) -> 29.809333 | M10: ="" | N10: =AVERAGE(G5:G16) -> 26.49325 | O10: =IFERROR(G10/G10,"") -> 1 | P10: =AVERAGEIFS($G:$G,$D:$D,D10,$C:$C,"<="&Source!$B$8)-AVERAGEIFS($G:$G,$C:$C,"<="&Source!$B$8) -> -0.81251667 | Q10: =G10-P10 -> 27.939517 | R10: =INTERCEPT($G$2:$G$61,$A$2:$A$61)+SLOPE($G$2:$G$61,$A$2:$A$61)*A10 -> 16.011033 | S10: =G10-R10 -> 11.115967 | T10: =ABS(S10) -> 11.115967 | U10: =IFERROR((S10-AVERAGE($S$2:$S$61))/stdev.s($S$2:$S$61),"") -> 0.9916398 | V10: =IF(ABS(U10)>=Source!$B$10,"Anomaly","") | W10: =IF(A10<=12,"",G10-INDEX($G:$G,ROW()-12)) | X10: =IF(C10=2019,"Baseline",IF(C10<=2021,"COVID shock",IF(C10=2022,"Reopening","Recovery"))) -> Baseline | Y10: =IFERROR(ABS(S10/G10),"") -> 0.40977503
A11: 10 | B11: 43739 | C11: =YEAR(B11) -> 2019 | D11: =MONTH(B11) -> 10 | E11: =TEXT(B11,"mmm") -> Oct | F11: Asia and the Pacific | G11: 29.354 | H11: =IFERROR(LN(G11),"") -> 3.3794288 | I11: =IF(A11=1,"",G11-G10) -> 2.227 | J11: =IFERROR(G11/INDEX($G:$G,MATCH(DATE(C11-1,D11,1),$B:$B,0))-1,"") | K11: =AVERAGE(G9:G11) -> 28.949 | L11: =AVERAGE(G6:G11) -> 29.438167 | M11: ="" | N11: =AVERAGE(G6:G17) -> 23.940667 | O11: =IFERROR(G11/G11,"") -> 1 | P11: =AVERAGEIFS($G:$G,$D:$D,D11,$C:$C,"<="&Source!$B$8)-AVERAGEIFS($G:$G,$C:$C,"<="&Source!$B$8) -> 0.087883333 | Q11: =G11-P11 -> 29.266117 | R11: =INTERCEPT($G$2:$G$61,$A$2:$A$61)+SLOPE($G$2:$G$61,$A$2:$A$61)*A11 -> 15.870079 | S11: =G11-R11 -> 13.483921 | T11: =ABS(S11) -> 13.483921 | U11: =IFERROR((S11-AVERAGE($S$2:$S$61))/stdev.s($S$2:$S$61),"") -> 1.2028817 | V11: =IF(ABS(U11)>=Source!$B$10,"Anomaly","") | W11: =IF(A11<=12,"",G11-INDEX($G:$G,ROW()-12)) | X11: =IF(C11=2019,"Baseline",IF(C11<=2021,"COVID shock",IF(C11=2022,"Reopening","Recovery"))) -> Baseline | Y11: =IFERROR(ABS(S11/G11),"") -> 0.4593555
A12: 11 | B12: 43770 | C12: =YEAR(B12) -> 2019 | D12: =MONTH(B12) -> 11 | E12: =TEXT(B12,"mmm") -> Nov | F12: Asia and the Pacific | G12: 29.556 | H12: =IFERROR(LN(G12),"") -> 3.3862868 | I12: =IF(A12=1,"",G12-G11) -> 0.202 | J12: =IFERROR(G12/INDEX($G:$G,MATCH(DATE(C12-1,D12,1),$B:$B,0))-1,"") | K12: =AVERAGE(G10:G12) -> 28.679 | L12: =AVERAGE(G7:G12) -> 29.471833 | M12: ="" | N12: =AVERAGE(G7:G18) -> 21.573667 | O12: =IFERROR(G12/G12,"") -> 1 | P12: =AVERAGEIFS($G:$G,$D:$D,D12,$C:$C,"<="&Source!$B$8)-AVERAGEIFS($G:$G,$C:$C,"<="&Source!$B$8) -> 0.67228333 | Q12: =G12-P12 -> 28.883717 | R12: =INTERCEPT($G$2:$G$61,$A$2:$A$61)+SLOPE($G$2:$G$61,$A$2:$A$61)*A12 -> 15.729124 | S12: =G12-R12 -> 13.826876 | T12: =ABS(S12) -> 13.826876 | U12: =IFERROR((S12-AVERAGE($S$2:$S$61))/stdev.s($S$2:$S$61),"") -> 1.2334761 | V12: =IF(ABS(U12)>=Source!$B$10,"Anomaly","") | W12: =IF(A12<=12,"",G12-INDEX($G:$G,ROW()-12)) | X12: =IF(C12=2019,"Baseline",IF(C12<=2021,"COVID shock",IF(C12=2022,"Reopening","Recovery"))) -> Baseline | Y12: =IFERROR(ABS(S12/G12),"") -> 0.46781959
A13: 12 | B13: 43800 | C13: =YEAR(B13) -> 2019 | D13: =MONTH(B13) -> 12 | E13: =TEXT(B13,"mmm") -> Dec | F13: Asia and the Pacific | G13: 31.682 | H13: =IFERROR(LN(G13),"") -> 3.4557487 | I13: =IF(A13=1,"",G13-G12) -> 2.126 | J13: =IFERROR(G13/INDEX($G:$G,MATCH(DATE(C13-1,D13,1),$B:$B,0))-1,"") | K13: =AVERAGE(G11:G13) -> 30.197333 | L13: =AVERAGE(G8:G13) -> 29.826167 | M13: =AVERAGE(G2:G13) -> 30.222583 | N13: =AVERAGE(G8:G19) -> 19.189833 | O13: =IFERROR(G13/G13,"") -> 1 | P13: =AVERAGEIFS($G:$G,$D:$D,D13,$C:$C,"<="&Source!$B$8)-AVERAGEIFS($G:$G,$C:$C,"<="&Source!$B$8) -> 2.6204833 | Q13: =G13-P13 -> 29.061517 | R13: =INTERCEPT($G$2:$G$61,$A$2:$A$61)+SLOPE($G$2:$G$61,$A$2:$A$61)*A13 -> 15.58817 | S13: =G13-R13 -> 16.09383 | T13: =ABS(S13) -> 16.09383 | U13: =IFERROR((S13-AVERAGE($S$2:$S$61))/stdev.s($S$2:$S$61),"") -> 1.4357079 | V13: =IF(ABS(U13)>=Source!$B$10,"Anomaly","") | W13: =IF(A13<=12,"",G13-INDEX($G:$G,ROW()-12)) | X13: =IF(C13=2019,"Baseline",IF(C13<=2021,"COVID shock",IF(C13=2022,"Reopening","Recovery"))) -> Baseline | Y13: =IFERROR(ABS(S13/G13),"") -> 0.50798024
A14: 13 | B14: 43831 | C14: =YEAR(B14) -> 2020 | D14: =MONTH(B14) -> 1 | E14: =TEXT(B14,"mmm") -> Jan | F14: Asia and the Pacific | G14: 28.512 | H14: =IFERROR(LN(G14),"") -> 3.3503251 | I14: =IF(A14=1,"",G14-G13) -> -3.17 | J14: =IFERROR(G14/INDEX($G:$G,MATCH(DATE(C14-1,D14,1),$B:$B,0))-1,"") -> -0.076444675 | K14: =AVERAGE(G12:G14) -> 29.916667 | L14: =AVERAGE(G9:G14) -> 29.432833 | M14: =AVERAGE(G3:G14) -> 30.025917 | N14: =AVERAGE(G9:G20) -> 16.736 | O14: =IFERROR(G14/G2,"") -> 0.92355533 | P14: =AVERAGEIFS($G:$G,$D:$D,D14,$C:$C,"<="&Source!$B$8)-AVERAGEIFS($G:$G,$C:$C,"<="&Source!$B$8) -> 2.6040833 | Q14: =G14-P14 -> 25.907917 | R14: =INTERCEPT($G$2:$G$61,$A$2:$A$61)+SLOPE($G$2:$G$61,$A$2:$A$61)*A14 -> 15.447216 | S14: =G14-R14 -> 13.064784 | T14: =ABS(S14) -> 13.064784 | U14: =IFERROR((S14-AVERAGE($S$2:$S$61))/stdev.s($S$2:$S$61),"") -> 1.165491 | V14: =IF(ABS(U14)>=Source!$B$10,"Anomaly","") | W14: =IF(A14<=12,"",G14-INDEX($G:$G,ROW()-12)) -> -2.36 | X14: =IF(C14=2019,"Baseline",IF(C14<=2021,"COVID shock",IF(C14=2022,"Reopening","Recovery"))) -> COVID shock | Y14: =IFERROR(ABS(S14/G14),"") -> 0.45822055
A15: 14 | B15: 43862 | C15: =YEAR(B15) -> 2020 | D15: =MONTH(B15) -> 2 | E15: =TEXT(B15,"mmm") -> Feb | F15: Asia and the Pacific | G15: 16.157 | H15: =IFERROR(LN(G15),"") -> 2.7823534 | I15: =IF(A15=1,"",G15-G14) -> -12.355 | J15: =IFERROR(G15/INDEX($G:$G,MATCH(DATE(C15-1,D15,1),$B:$B,0))-1,"") -> -0.46792465 | K15: =AVERAGE(G13:G15) -> 25.450333 | L15: =AVERAGE(G10:G15) -> 27.064667 | M15: =AVERAGE(G4:G15) -> 28.841833 | N15: =AVERAGE(G10:G21) -> 14.4035 | O15: =IFERROR(G15/G3,"") -> 0.53207535 | P15: =AVERAGEIFS($G:$G,$D:$D,D15,$C:$C,"<="&Source!$B$8)-AVERAGEIFS($G:$G,$C:$C,"<="&Source!$B$8) -> 0.25428333 | Q15: =G15-P15 -> 15.902717 | R15: =INTERCEPT($G$2:$G$61,$A$2:$A$61)+SLOPE($G$2:$G$61,$A$2:$A$61)*A15 -> 15.306262 | S15: =G15-R15 -> 0.85073842 | T15: =ABS(S15) -> 0.85073842 | U15: =IFERROR((S15-AVERAGE($S$2:$S$61))/stdev.s($S$2:$S$61),"") -> 0.075893178 | V15: =IF(ABS(U15)>=Source!$B$10,"Anomaly","") | W15: =IF(A15<=12,"",G15-INDEX($G:$G,ROW()-12)) -> -14.209 | X15: =IF(C15=2019,"Baseline",IF(C15<=2021,"COVID shock",IF(C15=2022,"Reopening","Recovery"))) -> COVID shock | Y15: =IFERROR(ABS(S15/G15),"") -> 0.052654479
A16: 15 | B16: 43891 | C16: =YEAR(B16) -> 2020 | D16: =MONTH(B16) -> 3 | E16: =TEXT(B16,"mmm") -> Mar | F16: Asia and the Pacific | G16: 3.802 | H16: =IFERROR(LN(G16),"") -> 1.3355272 | I16: =IF(A16=1,"",G16-G15) -> -12.355 | J16: =IFERROR(G16/INDEX($G:$G,MATCH(DATE(C16-1,D16,1),$B:$B,0))-1,"") -> -0.88113178 | K16: =AVERAGE(G14:G16) -> 16.157 | L16: =AVERAGE(G11:G16) -> 23.177167 | M16: =AVERAGE(G5:G16) -> 26.49325 | N16: =AVERAGE(G11:G22) -> 12.301333 | O16: =IFERROR(G16/G4,"") -> 0.11886822 | P16: =AVERAGEIFS($G:$G,$D:$D,D16,$C:$C,"<="&Source!$B$8)-AVERAGEIFS($G:$G,$C:$C,"<="&Source!$B$8) -> -1.3653167 | Q16: =G16-P16 -> 5.1673167 | R16: =INTERCEPT($G$2:$G$61,$A$2:$A$61)+SLOPE($G$2:$G$61,$A$2:$A$61)*A16 -> 15.165307 | S16: =G16-R16 -> -11.363307 | T16: =ABS(S16) -> 11.363307 | U16: =IFERROR((S16-AVERAGE($S$2:$S$61))/stdev.s($S$2:$S$61),"") -> -1.0137047 | V16: =IF(ABS(U16)>=Source!$B$10,"Anomaly","") | W16: =IF(A16<=12,"",G16-INDEX($G:$G,ROW()-12)) -> -28.183 | X16: =IF(C16=2019,"Baseline",IF(C16<=2021,"COVID shock",IF(C16=2022,"Reopening","Recovery"))) -> COVID shock | Y16: =IFERROR(ABS(S16/G16),"") -> 2.988771
A17: 16 | B17: 43922 | C17: =YEAR(B17) -> 2020 | D17: =MONTH(B17) -> 4 | E17: =TEXT(B17,"mmm") -> Apr | F17: Asia and the Pacific | G17: 0.95 | H17: =IFERROR(LN(G17),"") -> -0.051293294 | I17: =IF(A17=1,"",G17-G16) -> -2.852 | J17: =IFERROR(G17/INDEX($G:$G,MATCH(DATE(C17-1,D17,1),$B:$B,0))-1,"") -> -0.96991862 | K17: =AVERAGE(G15:G17) -> 6.9696667 | L17: =AVERAGE(G12:G17) -> 18.443167 | M17: =AVERAGE(G6:G17) -> 23.940667 | N17: =AVERAGE(G12:G23) -> 9.9185 | O17: =IFERROR(G17/G5,"") -> 0.030081378 | P17: =AVERAGEIFS($G:$G,$D:$D,D17,$C:$C,"<="&Source!$B$8)-AVERAGEIFS($G:$G,$C:$C,"<="&Source!$B$8) -> -1.5993167 | Q17: =G17-P17 -> 2.5493167 | R17: =INTERCEPT($G$2:$G$61,$A$2:$A$61)+SLOPE($G$2:$G$61,$A$2:$A$61)*A17 -> 15.024353 | S17: =G17-R17 -> -14.074353 | T17: =ABS(S17) -> 14.074353 | U17: =IFERROR((S17-AVERAGE($S$2:$S$61))/stdev.s($S$2:$S$61),"") -> -1.2555532 | V17: =IF(ABS(U17)>=Source!$B$10,"Anomaly","") | W17: =IF(A17<=12,"",G17-INDEX($G:$G,ROW()-12)) -> -30.631 | X17: =IF(C17=2019,"Baseline",IF(C17<=2021,"COVID shock",IF(C17=2022,"Reopening","Recovery"))) -> COVID shock | Y17: =IFERROR(ABS(S17/G17),"") -> 14.815109
A18: 17 | B18: 43952 | C18: =YEAR(B18) -> 2020 | D18: =MONTH(B18) -> 5 | E18: =TEXT(B18,"mmm") -> May | F18: Asia and the Pacific | G18: 0.95 | H18: =IFERROR(LN(G18),"") -> -0.051293294 | I18: =IF(A18=1,"",G18-G17) -> 0 | J18: =IFERROR(G18/INDEX($G:$G,MATCH(DATE(C18-1,D18,1),$B:$B,0))-1,"") -> -0.96763644 | K18: =AVERAGE(G16:G18) -> 1.9006667 | L18: =AVERAGE(G13:G18) -> 13.6755 | M18: =AVERAGE(G7:G18) -> 21.573667 | N18: =AVERAGE(G13:G24) -> 7.503 | O18: =IFERROR(G18/G6,"") -> 0.032363562 | P18: =AVERAGEIFS($G:$G,$D:$D,D18,$C:$C,"<="&Source!$B$8)-AVERAGEIFS($G:$G,$C:$C,"<="&Source!$B$8) -> -1.7461167 | Q18: =G18-P18 -> 2.6961167 | R18: =INTERCEPT($G$2:$G$61,$A$2:$A$61)+SLOPE($G$2:$G$61,$A$2:$A$61)*A18 -> 14.883399 | S18: =G18-R18 -> -13.933399 | T18: =ABS(S18) -> 13.933399 | U18: =IFERROR((S18-AVERAGE($S$2:$S$61))/stdev.s($S$2:$S$61),"") -> -1.2429789 | V18: =IF(ABS(U18)>=Source!$B$10,"Anomaly","") | W18: =IF(A18<=12,"",G18-INDEX($G:$G,ROW()-12)) -> -28.404 | X18: =IF(C18=2019,"Baseline",IF(C18<=2021,"COVID shock",IF(C18=2022,"Reopening","Recovery"))) -> COVID shock | Y18: =IFERROR(ABS(S18/G18),"") -> 14.666736
A19: 18 | B19: 43983 | C19: =YEAR(B19) -> 2020 | D19: =MONTH(B19) -> 6 | E19: =TEXT(B19,"mmm") -> Jun | F19: Asia and the Pacific | G19: 0.95 | H19: =IFERROR(LN(G19),"") -> -0.051293294 | I19: =IF(A19=1,"",G19-G18) -> 0 | J19: =IFERROR(G19/INDEX($G:$G,MATCH(DATE(C19-1,D19,1),$B:$B,0))-1,"") -> -0.96785763 | K19: =AVERAGE(G17:G19) -> 0.95 | L19: =AVERAGE(G14:G19) -> 8.5535 | M19: =AVERAGE(G8:G19) -> 19.189833 | N19: =AVERAGE(G14:G25) -> 4.9261667 | O19: =IFERROR(G19/G7,"") -> 0.032142374 | P19: =AVERAGEIFS($G:$G,$D:$D,D19,$C:$C,"<="&Source!$B$8)-AVERAGEIFS($G:$G,$C:$C,"<="&Source!$B$8) -> -1.1057167 | Q19: =G19-P19 -> 2.0557167 | R19: =INTERCEPT($G$2:$G$61,$A$2:$A$61)+SLOPE($G$2:$G$61,$A$2:$A$61)*A19 -> 14.742445 | S19: =G19-R19 -> -13.792445 | T19: =ABS(S19) -> 13.792445 | U19: =IFERROR((S19-AVERAGE($S$2:$S$61))/stdev.s($S$2:$S$61),"") -> -1.2304046 | V19: =IF(ABS(U19)>=Source!$B$10,"Anomaly","") | W19: =IF(A19<=12,"",G19-INDEX($G:$G,ROW()-12)) -> -28.606 | X19: =IF(C19=2019,"Baseline",IF(C19<=2021,"COVID shock",IF(C19=2022,"Reopening","Recovery"))) -> COVID shock | Y19: =IFERROR(ABS(S19/G19),"") -> 14.518363
A20: 19 | B20: 44013 | C20: =YEAR(B20) -> 2020 | D20: =MONTH(B20) -> 7 | E20: =TEXT(B20,"mmm") -> Jul | F20: Asia and the Pacific | G20: 1.426 | H20: =IFERROR(LN(G20),"") -> 0.35487332 | I20: =IF(A20=1,"",G20-G19) -> 0.476 | J20: =IFERROR(G20/INDEX($G:$G,MATCH(DATE(C20-1,D20,1),$B:$B,0))-1,"") -> -0.95380928 | K20: =AVERAGE(G18:G20) -> 1.1086667 | L20: =AVERAGE(G15:G20) -> 4.0391667 | M20: =AVERAGE(G9:G20) -> 16.736 | N20: =AVERAGE(G15:G26) -> 2.6765 | O20: =IFERROR(G20/G8,"") -> 0.046190723 | P20: =AVERAGEIFS($G:$G,$D:$D,D20,$C:$C,"<="&Source!$B$8)-AVERAGEIFS($G:$G,$C:$C,"<="&Source!$B$8) -> 0.12048333 | Q20: =G20-P20 -> 1.3055167 | R20: =INTERCEPT($G$2:$G$61,$A$2:$A$61)+SLOPE($G$2:$G$61,$A$2:$A$61)*A20 -> 14.60149 | S20: =G20-R20 -> -13.17549 | T20: =ABS(S20) -> 13.17549 | U20: =IFERROR((S20-AVERAGE($S$2:$S$61))/stdev.s($S$2:$S$61),"") -> -1.175367 | V20: =IF(ABS(U20)>=Source!$B$10,"Anomaly","") | W20: =IF(A20<=12,"",G20-INDEX($G:$G,ROW()-12)) -> -29.446 | X20: =IF(C20=2019,"Baseline",IF(C20<=2021,"COVID shock",IF(C20=2022,"Reopening","Recovery"))) -> COVID shock | Y20: =IFERROR(ABS(S20/G20),"") -> 9.2394743
A21: 20 | B21: 44044 | C21: =YEAR(B21) -> 2020 | D21: =MONTH(B21) -> 8 | E21: =TEXT(B21,"mmm") -> Aug | F21: Asia and the Pacific | G21: 2.376 | H21: =IFERROR(LN(G21),"") -> 0.8654184 | I21: =IF(A21=1,"",G21-G20) -> 0.95 | J21: =IFERROR(G21/INDEX($G:$G,MATCH(DATE(C21-1,D21,1),$B:$B,0))-1,"") -> -0.92175459 | K21: =AVERAGE(G19:G21) -> 1.584 | L21: =AVERAGE(G16:G21) -> 1.7423333 | M21: =AVERAGE(G10:G21) -> 14.4035 | N21: =AVERAGE(G16:G27) -> 1.4564167 | O21: =IFERROR(G21/G9,"") -> 0.078245406 | P21: =AVERAGEIFS($G:$G,$D:$D,D21,$C:$C,"<="&Source!$B$8)-AVERAGEIFS($G:$G,$C:$C,"<="&Source!$B$8) -> 0.26948333 | Q21: =G21-P21 -> 2.1065167 | R21: =INTERCEPT($G$2:$G$61,$A$2:$A$61)+SLOPE($G$2:$G$61,$A$2:$A$61)*A21 -> 14.460536 | S21: =G21-R21 -> -12.084536 | T21: =ABS(S21) -> 12.084536 | U21: =IFERROR((S21-AVERAGE($S$2:$S$61))/stdev.s($S$2:$S$61),"") -> -1.0780445 | V21: =IF(ABS(U21)>=Source!$B$10,"Anomaly","") | W21: =IF(A21<=12,"",G21-INDEX($G:$G,ROW()-12)) -> -27.99 | X21: =IF(C21=2019,"Baseline",IF(C21<=2021,"COVID shock",IF(C21=2022,"Reopening","Recovery"))) -> COVID shock | Y21: =IFERROR(ABS(S21/G21),"") -> 5.0860842
A22: 21 | B22: 44075 | C22: =YEAR(B22) -> 2020 | D22: =MONTH(B22) -> 9 | E22: =TEXT(B22,"mmm") -> Sep | F22: Asia and the Pacific | G22: 1.901 | H22: =IFERROR(LN(G22),"") -> 0.64238006 | I22: =IF(A22=1,"",G22-G21) -> -0.475 | J22: =IFERROR(G22/INDEX($G:$G,MATCH(DATE(C22-1,D22,1),$B:$B,0))-1,"") -> -0.92992222 | K22: =AVERAGE(G20:G22) -> 1.901 | L22: =AVERAGE(G17:G22) -> 1.4255 | M22: =AVERAGE(G11:G22) -> 12.301333 | N22: =AVERAGE(G17:G28) -> 1.28275 | O22: =IFERROR(G22/G10,"") -> 0.070077782 | P22: =AVERAGEIFS($G:$G,$D:$D,D22,$C:$C,"<="&Source!$B$8)-AVERAGEIFS($G:$G,$C:$C,"<="&Source!$B$8) -> -0.81251667 | Q22: =G22-P22 -> 2.7135167 | R22: =INTERCEPT($G$2:$G$61,$A$2:$A$61)+SLOPE($G$2:$G$61,$A$2:$A$61)*A22 -> 14.319582 | S22: =G22-R22 -> -12.418582 | T22: =ABS(S22) -> 12.418582 | U22: =IFERROR((S22-AVERAGE($S$2:$S$61))/stdev.s($S$2:$S$61),"") -> -1.1078442 | V22: =IF(ABS(U22)>=Source!$B$10,"Anomaly","") | W22: =IF(A22<=12,"",G22-INDEX($G:$G,ROW()-12)) -> -25.226 | X22: =IF(C22=2019,"Baseline",IF(C22<=2021,"COVID shock",IF(C22=2022,"Reopening","Recovery"))) -> COVID shock | Y22: =IFERROR(ABS(S22/G22),"") -> 6.5326575
A23: 22 | B23: 44105 | C23: =YEAR(B23) -> 2020 | D23: =MONTH(B23) -> 10 | E23: =TEXT(B23,"mmm") -> Oct | F23: Asia and the Pacific | G23: 0.76 | H23: =IFERROR(LN(G23),"") -> -0.27443685 | I23: =IF(A23=1,"",G23-G22) -> -1.141 | J23: =IFERROR(G23/INDEX($G:$G,MATCH(DATE(C23-1,D23,1),$B:$B,0))-1,"") -> -0.97410915 | K23: =AVERAGE(G21:G23) -> 1.679 | L23: =AVERAGE(G18:G23) -> 1.3938333 | M23: =AVERAGE(G12:G23) -> 9.9185 | N23: =AVERAGE(G18:G29) -> 1.372 | O23: =IFERROR(G23/G11,"") -> 0.02589085 | P23: =AVERAGEIFS($G:$G,$D:$D,D23,$C:$C,"<="&Source!$B$8)-AVERAGEIFS($G:$G,$C:$C,"<="&Source!$B$8) -> 0.087883333 | Q23: =G23-P23 -> 0.67211667 | R23: =INTERCEPT($G$2:$G$61,$A$2:$A$61)+SLOPE($G$2:$G$61,$A$2:$A$61)*A23 -> 14.178628 | S23: =G23-R23 -> -13.418628 | T23: =ABS(S23) -> 13.418628 | U23: =IFERROR((S23-AVERAGE($S$2:$S$61))/stdev.s($S$2:$S$61),"") -> -1.1970569 | V23: =IF(ABS(U23)>=Source!$B$10,"Anomaly","") | W23: =IF(A23<=12,"",G23-INDEX($G:$G,ROW()-12)) -> -28.594 | X23: =IF(C23=2019,"Baseline",IF(C23<=2021,"COVID shock",IF(C23=2022,"Reopening","Recovery"))) -> COVID shock | Y23: =IFERROR(ABS(S23/G23),"") -> 17.656089
A24: 23 | B24: 44136 | C24: =YEAR(B24) -> 2020 | D24: =MONTH(B24) -> 11 | E24: =TEXT(B24,"mmm") -> Nov | F24: Asia and the Pacific | G24: 0.57 | H24: =IFERROR(LN(G24),"") -> -0.56211892 | I24: =IF(A24=1,"",G24-G23) -> -0.19 | J24: =IFERROR(G24/INDEX($G:$G,MATCH(DATE(C24-1,D24,1),$B:$B,0))-1,"") -> -0.98071458 | K24: =AVERAGE(G22:G24) -> 1.077 | L24: =AVERAGE(G19:G24) -> 1.3305 | M24: =AVERAGE(G13:G24) -> 7.503 | N24: =AVERAGE(G19:G30) -> 1.46125 | O24: =IFERROR(G24/G12,"") -> 0.019285424 | P24: =AVERAGEIFS($G:$G,$D:$D,D24,$C:$C,"<="&Source!$B$8)-AVERAGEIFS($G:$G,$C:$C,"<="&Source!$B$8) -> 0.67228333 | Q24: =G24-P24 -> -0.10228333 | R24: =INTERCEPT($G$2:$G$61,$A$2:$A$61)+SLOPE($G$2:$G$61,$A$2:$A$61)*A24 -> 14.037673 | S24: =G24-R24 -> -13.467673 | T24: =ABS(S24) -> 13.467673 | U24: =IFERROR((S24-AVERAGE($S$2:$S$61))/stdev.s($S$2:$S$61),"") -> -1.2014322 | V24: =IF(ABS(U24)>=Source!$B$10,"Anomaly","") | W24: =IF(A24<=12,"",G24-INDEX($G:$G,ROW()-12)) -> -28.986 | X24: =IF(C24=2019,"Baseline",IF(C24<=2021,"COVID shock",IF(C24=2022,"Reopening","Recovery"))) -> COVID shock | Y24: =IFERROR(ABS(S24/G24),"") -> 23.627497
A25: 24 | B25: 44166 | C25: =YEAR(B25) -> 2020 | D25: =MONTH(B25) -> 12 | E25: =TEXT(B25,"mmm") -> Dec | F25: Asia and the Pacific | G25: 0.76 | H25: =IFERROR(LN(G25),"") -> -0.27443685 | I25: =IF(A25=1,"",G25-G24) -> 0.19 | J25: =IFERROR(G25/INDEX($G:$G,MATCH(DATE(C25-1,D25,1),$B:$B,0))-1,"") -> -0.97601162 | K25: =AVERAGE(G23:G25) -> 0.69666667 | L25: =AVERAGE(G20:G25) -> 1.2988333 | M25: =AVERAGE(G14:G25) -> 4.9261667 | N25: =AVERAGE(G20:G31) -> 1.5505 | O25: =IFERROR(G25/G13,"") -> 0.023988385 | P25: =AVERAGEIFS($G:$G,$D:$D,D25,$C:$C,"<="&Source!$B$8)-AVERAGEIFS($G:$G,$C:$C,"<="&Source!$B$8) -> 2.6204833 | Q25: =G25-P25 -> -1.8604833 | R25: =INTERCEPT($G$2:$G$61,$A$2:$A$61)+SLOPE($G$2:$G$61,$A$2:$A$61)*A25 -> 13.896719 | S25: =G25-R25 -> -13.136719 | T25: =ABS(S25) -> 13.136719 | U25: =IFERROR((S25-AVERAGE($S$2:$S$61))/stdev.s($S$2:$S$61),"") -> -1.1719082 | V25: =IF(ABS(U25)>=Source!$B$10,"Anomaly","") | W25: =IF(A25<=12,"",G25-INDEX($G:$G,ROW()-12)) -> -30.922 | X25: =IF(C25=2019,"Baseline",IF(C25<=2021,"COVID shock",IF(C25=2022,"Reopening","Recovery"))) -> COVID shock | Y25: =IFERROR(ABS(S25/G25),"") -> 17.285157
A26: 25 | B26: 44197 | C26: =YEAR(B26) -> 2021 | D26: =MONTH(B26) -> 1 | E26: =TEXT(B26,"mmm") -> Jan | F26: Asia and the Pacific | G26: 1.516 | H26: =IFERROR(LN(G26),"") -> 0.41607529 | I26: =IF(A26=1,"",G26-G25) -> 0.756 | J26: =IFERROR(G26/INDEX($G:$G,MATCH(DATE(C26-1,D26,1),$B:$B,0))-1,"") -> -0.94682941 | K26: =AVERAGE(G24:G26) -> 0.94866667 | L26: =AVERAGE(G21:G26) -> 1.3138333 | M26: =AVERAGE(G15:G26) -> 2.6765 | N26: =AVERAGE(G21:G32) -> 1.6253333 | O26: =IFERROR(G26/G2,"") -> 0.049105986 | P26: =AVERAGEIFS($G:$G,$D:$D,D26,$C:$C,"<="&Source!$B$8)-AVERAGEIFS($G:$G,$C:$C,"<="&Source!$B$8) -> 2.6040833 | Q26: =G26-P26 -> -1.0880833 | R26: =INTERCEPT($G$2:$G$61,$A$2:$A$61)+SLOPE($G$2:$G$61,$A$2:$A$61)*A26 -> 13.755765 | S26: =G26-R26 -> -12.239765 | T26: =ABS(S26) -> 12.239765 | U26: =IFERROR((S26-AVERAGE($S$2:$S$61))/stdev.s($S$2:$S$61),"") -> -1.0918922 | V26: =IF(ABS(U26)>=Source!$B$10,"Anomaly","") | W26: =IF(A26<=12,"",G26-INDEX($G:$G,ROW()-12)) -> -26.996 | X26: =IF(C26=2019,"Baseline",IF(C26<=2021,"COVID shock",IF(C26=2022,"Reopening","Recovery"))) -> COVID shock | Y26: =IFERROR(ABS(S26/G26),"") -> 8.0737236
A27: 26 | B27: 44228 | C27: =YEAR(B27) -> 2021 | D27: =MONTH(B27) -> 2 | E27: =TEXT(B27,"mmm") -> Feb | F27: Asia and the Pacific | G27: 1.516 | H27: =IFERROR(LN(G27),"") -> 0.41607529 | I27: =IF(A27=1,"",G27-G26) -> 0 | J27: =IFERROR(G27/INDEX($G:$G,MATCH(DATE(C27-1,D27,1),$B:$B,0))-1,"") -> -0.9061707 | K27: =AVERAGE(G25:G27) -> 1.264 | L27: =AVERAGE(G22:G27) -> 1.1705 | M27: =AVERAGE(G16:G27) -> 1.4564167 | N27: =AVERAGE(G22:G33) -> 1.6041667 | O27: =IFERROR(G27/G3,"") -> 0.049924257 | P27: =AVERAGEIFS($G:$G,$D:$D,D27,$C:$C,"<="&Source!$B$8)-AVERAGEIFS($G:$G,$C:$C,"<="&Source!$B$8) -> 0.25428333 | Q27: =G27-P27 -> 1.2617167 | R27: =INTERCEPT($G$2:$G$61,$A$2:$A$61)+SLOPE($G$2:$G$61,$A$2:$A$61)*A27 -> 13.614811 | S27: =G27-R27 -> -12.098811 | T27: =ABS(S27) -> 12.098811 | U27: =IFERROR((S27-AVERAGE($S$2:$S$61))/stdev.s($S$2:$S$61),"") -> -1.0793179 | V27: =IF(ABS(U27)>=Source!$B$10,"Anomaly","") | W27: =IF(A27<=12,"",G27-INDEX($G:$G,ROW()-12)) -> -14.641 | X27: =IF(C27=2019,"Baseline",IF(C27<=2021,"COVID shock",IF(C27=2022,"Reopening","Recovery"))) -> COVID shock | Y27: =IFERROR(ABS(S27/G27),"") -> 7.9807459
A28: 27 | B28: 44256 | C28: =YEAR(B28) -> 2021 | D28: =MONTH(B28) -> 3 | E28: =TEXT(B28,"mmm") -> Mar | F28: Asia and the Pacific | G28: 1.718 | H28: =IFERROR(LN(G28),"") -> 0.54116082 | I28: =IF(A28=1,"",G28-G27) -> 0.202 | J28: =IFERROR(G28/INDEX($G:$G,MATCH(DATE(C28-1,D28,1),$B:$B,0))-1,"") -> -0.54813256 | K28: =AVERAGE(G26:G28) -> 1.5833333 | L28: =AVERAGE(G23:G28) -> 1.14 | M28: =AVERAGE(G17:G28) -> 1.28275 | N28: =AVERAGE(G23:G34) -> 1.6141667 | O28: =IFERROR(G28/G4,"") -> 0.053712678 | P28: =AVERAGEIFS($G:$G,$D:$D,D28,$C:$C,"<="&Source!$B$8)-AVERAGEIFS($G:$G,$C:$C,"<="&Source!$B$8) -> -1.3653167 | Q28: =G28-P28 -> 3.0833167 | R28: =INTERCEPT($G$2:$G$61,$A$2:$A$61)+SLOPE($G$2:$G$61,$A$2:$A$61)*A28 -> 13.473856 | S28: =G28-R28 -> -11.755856 | T28: =ABS(S28) -> 11.755856 | U28: =IFERROR((S28-AVERAGE($S$2:$S$61))/stdev.s($S$2:$S$61),"") -> -1.0487234 | V28: =IF(ABS(U28)>=Source!$B$10,"Anomaly","") | W28: =IF(A28<=12,"",G28-INDEX($G:$G,ROW()-12)) -> -2.084 | X28: =IF(C28=2019,"Baseline",IF(C28<=2021,"COVID shock",IF(C28=2022,"Reopening","Recovery"))) -> COVID shock | Y28: =IFERROR(ABS(S28/G28),"") -> 6.842757
A29: 28 | B29: 44287 | C29: =YEAR(B29) -> 2021 | D29: =MONTH(B29) -> 4 | E29: =TEXT(B29,"mmm") -> Apr | F29: Asia and the Pacific | G29: 2.021 | H29: =IFERROR(LN(G29),"") -> 0.70359244 | I29: =IF(A29=1,"",G29-G28) -> 0.303 | J29: =IFERROR(G29/INDEX($G:$G,MATCH(DATE(C29-1,D29,1),$B:$B,0))-1,"") -> 1.1273684 | K29: =AVERAGE(G27:G29) -> 1.7516667 | L29: =AVERAGE(G24:G29) -> 1.3501667 | M29: =AVERAGE(G18:G29) -> 1.372 | N29: =AVERAGE(G24:G35) -> 1.7445 | O29: =IFERROR(G29/G5,"") -> 0.063994174 | P29: =AVERAGEIFS($G:$G,$D:$D,D29,$C:$C,"<="&Source!$B$8)-AVERAGEIFS($G:$G,$C:$C,"<="&Source!$B$8) -> -1.5993167 | Q29: =G29-P29 -> 3.6203167 | R29: =INTERCEPT($G$2:$G$61,$A$2:$A$61)+SLOPE($G$2:$G$61,$A$2:$A$61)*A29 -> 13.332902 | S29: =G29-R29 -> -11.311902 | T29: =ABS(S29) -> 11.311902 | U29: =IFERROR((S29-AVERAGE($S$2:$S$61))/stdev.s($S$2:$S$61),"") -> -1.0091189 | V29: =IF(ABS(U29)>=Source!$B$10,"Anomaly","") | W29: =IF(A29<=12,"",G29-INDEX($G:$G,ROW()-12)) -> 1.071 | X29: =IF(C29=2019,"Baseline",IF(C29<=2021,"COVID shock",IF(C29=2022,"Reopening","Recovery"))) -> COVID shock | Y29: =IFERROR(ABS(S29/G29),"") -> 5.5971807
A30: 29 | B30: 44317 | C30: =YEAR(B30) -> 2021 | D30: =MONTH(B30) -> 5 | E30: =TEXT(B30,"mmm") -> May | F30: Asia and the Pacific | G30: 2.021 | H30: =IFERROR(LN(G30),"") -> 0.70359244 | I30: =IF(A30=1,"",G30-G29) -> 0 | J30: =IFERROR(G30/INDEX($G:$G,MATCH(DATE(C30-1,D30,1),$B:$B,0))-1,"") -> 1.1273684 | K30: =AVERAGE(G28:G30) -> 1.92 | L30: =AVERAGE(G25:G30) -> 1.592 | M30: =AVERAGE(G19:G30) -> 1.46125 | N30: =AVERAGE(G25:G36) -> 1.9495833 | O30: =IFERROR(G30/G6,"") -> 0.06884922 | P30: =AVERAGEIFS($G:$G,$D:$D,D30,$C:$C,"<="&Source!$B$8)-AVERAGEIFS($G:$G,$C:$C,"<="&Source!$B$8) -> -1.7461167 | Q30: =G30-P30 -> 3.7671167 | R30: =INTERCEPT($G$2:$G$61,$A$2:$A$61)+SLOPE($G$2:$G$61,$A$2:$A$61)*A30 -> 13.191948 | S30: =G30-R30 -> -11.170948 | T30: =ABS(S30) -> 11.170948 | U30: =IFERROR((S30-AVERAGE($S$2:$S$61))/stdev.s($S$2:$S$61),"") -> -0.99654456 | V30: =IF(ABS(U30)>=Source!$B$10,"Anomaly","") | W30: =IF(A30<=12,"",G30-INDEX($G:$G,ROW()-12)) -> 1.071 | X30: =IF(C30=2019,"Baseline",IF(C30<=2021,"COVID shock",IF(C30=2022,"Reopening","Recovery"))) -> COVID shock | Y30: =IFERROR(ABS(S30/G30),"") -> 5.5274359
A31: 30 | B31: 44348 | C31: =YEAR(B31) -> 2021 | D31: =MONTH(B31) -> 6 | E31: =TEXT(B31,"mmm") -> Jun | F31: Asia and the Pacific | G31: 2.021 | H31: =IFERROR(LN(G31),"") -> 0.70359244 | I31: =IF(A31=1,"",G31-G30) -> 0 | J31: =IFERROR(G31/INDEX($G:$G,MATCH(DATE(C31-1,D31,1),$B:$B,0))-1,"") -> 1.1273684 | K31: =AVERAGE(G29:G31) -> 2.021 | L31: =AVERAGE(G26:G31) -> 1.8021667 | M31: =AVERAGE(G20:G31) -> 1.5505 | N31: =AVERAGE(G26:G37) -> 2.20625 | O31: =IFERROR(G31/G7,"") -> 0.068378671 | P31: =AVERAGEIFS($G:$G,$D:$D,D31,$C:$C,"<="&Source!$B$8)-AVERAGEIFS($G:$G,$C:$C,"<="&Source!$B$8) -> -1.1057167 | Q31: =G31-P31 -> 3.1267167 | R31: =INTERCEPT($G$2:$G$61,$A$2:$A$61)+SLOPE($G$2:$G$61,$A$2:$A$61)*A31 -> 13.050994 | S31: =G31-R31 -> -11.029994 | T31: =ABS(S31) -> 11.029994 | U31: =IFERROR((S31-AVERAGE($S$2:$S$61))/stdev.s($S$2:$S$61),"") -> -0.98397023 | V31: =IF(ABS(U31)>=Source!$B$10,"Anomaly","") | W31: =IF(A31<=12,"",G31-INDEX($G:$G,ROW()-12)) -> 1.071 | X31: =IF(C31=2019,"Baseline",IF(C31<=2021,"COVID shock",IF(C31=2022,"Reopening","Recovery"))) -> COVID shock | Y31: =IFERROR(ABS(S31/G31),"") -> 5.4576911
A32: 31 | B32: 44378 | C32: =YEAR(B32) -> 2021 | D32: =MONTH(B32) -> 7 | E32: =TEXT(B32,"mmm") -> Jul | F32: Asia and the Pacific | G32: 2.324 | H32: =IFERROR(LN(G32),"") -> 0.84328984 | I32: =IF(A32=1,"",G32-G31) -> 0.303 | J32: =IFERROR(G32/INDEX($G:$G,MATCH(DATE(C32-1,D32,1),$B:$B,0))-1,"") -> 0.62973352 | K32: =AVERAGE(G30:G32) -> 2.122 | L32: =AVERAGE(G27:G32) -> 1.9368333 | M32: =AVERAGE(G21:G32) -> 1.6253333 | N32: =AVERAGE(G27:G38) -> 2.2843333 | O32: =IFERROR(G32/G8,"") -> 0.07527857 | P32: =AVERAGEIFS($G:$G,$D:$D,D32,$C:$C,"<="&Source!$B$8)-AVERAGEIFS($G:$G,$C:$C,"<="&Source!$B$8) -> 0.12048333 | Q32: =G32-P32 -> 2.2035167 | R32: =INTERCEPT($G$2:$G$61,$A$2:$A$61)+SLOPE($G$2:$G$61,$A$2:$A$61)*A32 -> 12.91004 | S32: =G32-R32 -> -10.58604 | T32: =ABS(S32) -> 10.58604 | U32: =IFERROR((S32-AVERAGE($S$2:$S$61))/stdev.s($S$2:$S$61),"") -> -0.9443657 | V32: =IF(ABS(U32)>=Source!$B$10,"Anomaly","") | W32: =IF(A32<=12,"",G32-INDEX($G:$G,ROW()-12)) -> 0.898 | X32: =IF(C32=2019,"Baseline",IF(C32<=2021,"COVID shock",IF(C32=2022,"Reopening","Recovery"))) -> COVID shock | Y32: =IFERROR(ABS(S32/G32),"") -> 4.5550945
A33: 32 | B33: 44409 | C33: =YEAR(B33) -> 2021 | D33: =MONTH(B33) -> 8 | E33: =TEXT(B33,"mmm") -> Aug | F33: Asia and the Pacific | G33: 2.122 | H33: =IFERROR(LN(G33),"") -> 0.75235904 | I33: =IF(A33=1,"",G33-G32) -> -0.202 | J33: =IFERROR(G33/INDEX($G:$G,MATCH(DATE(C33-1,D33,1),$B:$B,0))-1,"") -> -0.10690236 | K33: =AVERAGE(G31:G33) -> 2.1556667 | L33: =AVERAGE(G28:G33) -> 2.0378333 | M33: =AVERAGE(G22:G33) -> 1.6041667 | N33: =AVERAGE(G28:G39) -> 2.3713333 | O33: =IFERROR(G33/G9,"") -> 0.069880788 | P33: =AVERAGEIFS($G:$G,$D:$D,D33,$C:$C,"<="&Source!$B$8)-AVERAGEIFS($G:$G,$C:$C,"<="&Source!$B$8) -> 0.26948333 | Q33: =G33-P33 -> 1.8525167 | R33: =INTERCEPT($G$2:$G$61,$A$2:$A$61)+SLOPE($G$2:$G$61,$A$2:$A$61)*A33 -> 12.769085 | S33: =G33-R33 -> -10.647085 | T33: =ABS(S33) -> 10.647085 | U33: =IFERROR((S33-AVERAGE($S$2:$S$61))/stdev.s($S$2:$S$61),"") -> -0.9498115 | V33: =IF(ABS(U33)>=Source!$B$10,"Anomaly","") | W33: =IF(A33<=12,"",G33-INDEX($G:$G,ROW()-12)) -> -0.254 | X33: =IF(C33=2019,"Baseline",IF(C33<=2021,"COVID shock",IF(C33=2022,"Reopening","Recovery"))) -> COVID shock | Y33: =IFERROR(ABS(S33/G33),"") -> 5.0174766
A34: 33 | B34: 44440 | C34: =YEAR(B34) -> 2021 | D34: =MONTH(B34) -> 9 | E34: =TEXT(B34,"mmm") -> Sep | F34: Asia and the Pacific | G34: 2.021 | H34: =IFERROR(LN(G34),"") -> 0.70359244 | I34: =IF(A34=1,"",G34-G33) -> -0.101 | J34: =IFERROR(G34/INDEX($G:$G,MATCH(DATE(C34-1,D34,1),$B:$B,0))-1,"") -> 0.063124671 | K34: =AVERAGE(G32:G34) -> 2.1556667 | L34: =AVERAGE(G29:G34) -> 2.0883333 | M34: =AVERAGE(G23:G34) -> 1.6141667 | N34: =AVERAGE(G29:G40) -> 2.4770833 | O34: =IFERROR(G34/G10,"") -> 0.074501419 | P34: =AVERAGEIFS($G:$G,$D:$D,D34,$C:$C,"<="&Source!$B$8)-AVERAGEIFS($G:$G,$C:$C,"<="&Source!$B$8) -> -0.81251667 | Q34: =G34-P34 -> 2.8335167 | R34: =INTERCEPT($G$2:$G$61,$A$2:$A$61)+SLOPE($G$2:$G$61,$A$2:$A$61)*A34 -> 12.628131 | S34: =G34-R34 -> -10.607131 | T34: =ABS(S34) -> 10.607131 | U34: =IFERROR((S34-AVERAGE($S$2:$S$61))/stdev.s($S$2:$S$61),"") -> -0.94624724 | V34: =IF(ABS(U34)>=Source!$B$10,"Anomaly","") | W34: =IF(A34<=12,"",G34-INDEX($G:$G,ROW()-12)) -> 0.12 | X34: =IF(C34=2019,"Baseline",IF(C34<=2021,"COVID shock",IF(C34=2022,"Reopening","Recovery"))) -> COVID shock | Y34: =IFERROR(ABS(S34/G34),"") -> 5.2484567
A35: 34 | B35: 44470 | C35: =YEAR(B35) -> 2021 | D35: =MONTH(B35) -> 10 | E35: =TEXT(B35,"mmm") -> Oct | F35: Asia and the Pacific | G35: 2.324 | H35: =IFERROR(LN(G35),"") -> 0.84328984 | I35: =IF(A35=1,"",G35-G34) -> 0.303 | J35: =IFERROR(G35/INDEX($G:$G,MATCH(DATE(C35-1,D35,1),$B:$B,0))-1,"") -> 2.0578947 | K35: =AVERAGE(G33:G35) -> 2.1556667 | L35: =AVERAGE(G30:G35) -> 2.1388333 | M35: =AVERAGE(G24:G35) -> 1.7445 | N35: =AVERAGE(G30:G41) -> 2.66425 | O35: =IFERROR(G35/G11,"") -> 0.079171493 | P35: =AVERAGEIFS($G:$G,$D:$D,D35,$C:$C,"<="&Source!$B$8)-AVERAGEIFS($G:$G,$C:$C,"<="&Source!$B$8) -> 0.087883333 | Q35: =G35-P35 -> 2.2361167 | R35: =INTERCEPT($G$2:$G$61,$A$2:$A$61)+SLOPE($G$2:$G$61,$A$2:$A$61)*A35 -> 12.487177 | S35: =G35-R35 -> -10.163177 | T35: =ABS(S35) -> 10.163177 | U35: =IFERROR((S35-AVERAGE($S$2:$S$61))/stdev.s($S$2:$S$61),"") -> -0.90664271 | V35: =IF(ABS(U35)>=Source!$B$10,"Anomaly","") | W35: =IF(A35<=12,"",G35-INDEX($G:$G,ROW()-12)) -> 1.564 | X35: =IF(C35=2019,"Baseline",IF(C35<=2021,"COVID shock",IF(C35=2022,"Reopening","Recovery"))) -> COVID shock | Y35: =IFERROR(ABS(S35/G35),"") -> 4.3731398
A36: 35 | B36: 44501 | C36: =YEAR(B36) -> 2021 | D36: =MONTH(B36) -> 11 | E36: =TEXT(B36,"mmm") -> Nov | F36: Asia and the Pacific | G36: 3.031 | H36: =IFERROR(LN(G36),"") -> 1.1088926 | I36: =IF(A36=1,"",G36-G35) -> 0.707 | J36: =IFERROR(G36/INDEX($G:$G,MATCH(DATE(C36-1,D36,1),$B:$B,0))-1,"") -> 4.3175439 | K36: =AVERAGE(G34:G36) -> 2.4586667 | L36: =AVERAGE(G31:G36) -> 2.3071667 | M36: =AVERAGE(G25:G36) -> 1.9495833 | N36: =AVERAGE(G31:G42) -> 2.9758333 | O36: =IFERROR(G36/G12,"") -> 0.10255109 | P36: =AVERAGEIFS($G:$G,$D:$D,D36,$C:$C,"<="&Source!$B$8)-AVERAGEIFS($G:$G,$C:$C,"<="&Source!$B$8) -> 0.67228333 | Q36: =G36-P36 -> 2.3587167 | R36: =INTERCEPT($G$2:$G$61,$A$2:$A$61)+SLOPE($G$2:$G$61,$A$2:$A$61)*A36 -> 12.346223 | S36: =G36-R36 -> -9.3152226 | T36: =ABS(S36) -> 9.3152226 | U36: =IFERROR((S36-AVERAGE($S$2:$S$61))/stdev.s($S$2:$S$61),"") -> -0.83099791 | V36: =IF(ABS(U36)>=Source!$B$10,"Anomaly","") | W36: =IF(A36<=12,"",G36-INDEX($G:$G,ROW()-12)) -> 2.461 | X36: =IF(C36=2019,"Baseline",IF(C36<=2021,"COVID shock",IF(C36=2022,"Reopening","Recovery"))) -> COVID shock | Y36: =IFERROR(ABS(S36/G36),"") -> 3.0733166
A37: 36 | B37: 44531 | C37: =YEAR(B37) -> 2021 | D37: =MONTH(B37) -> 12 | E37: =TEXT(B37,"mmm") -> Dec | F37: Asia and the Pacific | G37: 3.84 | H37: =IFERROR(LN(G37),"") -> 1.3454724 | I37: =IF(A37=1,"",G37-G36) -> 0.809 | J37: =IFERROR(G37/INDEX($G:$G,MATCH(DATE(C37-1,D37,1),$B:$B,0))-1,"") -> 4.0526316 | K37: =AVERAGE(G35:G37) -> 3.065 | L37: =AVERAGE(G32:G37) -> 2.6103333 | M37: =AVERAGE(G26:G37) -> 2.20625 | N37: =AVERAGE(G32:G43) -> 3.4118333 | O37: =IFERROR(G37/G13,"") -> 0.12120447 | P37: =AVERAGEIFS($G:$G,$D:$D,D37,$C:$C,"<="&Source!$B$8)-AVERAGEIFS($G:$G,$C:$C,"<="&Source!$B$8) -> 2.6204833 | Q37: =G37-P37 -> 1.2195167 | R37: =INTERCEPT($G$2:$G$61,$A$2:$A$61)+SLOPE($G$2:$G$61,$A$2:$A$61)*A37 -> 12.205268 | S37: =G37-R37 -> -8.3652684 | T37: =ABS(S37) -> 8.3652684 | U37: =IFERROR((S37-AVERAGE($S$2:$S$61))/stdev.s($S$2:$S$61),"") -> -0.74625382 | V37: =IF(ABS(U37)>=Source!$B$10,"Anomaly","") | W37: =IF(A37<=12,"",G37-INDEX($G:$G,ROW()-12)) -> 3.08 | X37: =IF(C37=2019,"Baseline",IF(C37<=2021,"COVID shock",IF(C37=2022,"Reopening","Recovery"))) -> COVID shock | Y37: =IFERROR(ABS(S37/G37),"") -> 2.1784553
A38: 37 | B38: 44562 | C38: =YEAR(B38) -> 2022 | D38: =MONTH(B38) -> 1 | E38: =TEXT(B38,"mmm") -> Jan | F38: Asia and the Pacific | G38: 2.453 | H38: =IFERROR(LN(G38),"") -> 0.89731177 | I38: =IF(A38=1,"",G38-G37) -> -1.387 | J38: =IFERROR(G38/INDEX($G:$G,MATCH(DATE(C38-1,D38,1),$B:$B,0))-1,"") -> 0.61807388 | K38: =AVERAGE(G36:G38) -> 3.108 | L38: =AVERAGE(G33:G38) -> 2.6318333 | M38: =AVERAGE(G27:G38) -> 2.2843333 | N38: =AVERAGE(G33:G44) -> 3.9915 | O38: =IFERROR(G38/G2,"") -> 0.079457113 | P38: =AVERAGEIFS($G:$G,$D:$D,D38,$C:$C,"<="&Source!$B$8)-AVERAGEIFS($G:$G,$C:$C,"<="&Source!$B$8) -> 2.6040833 | Q38: =G38-P38 -> -0.15108333 | R38: =INTERCEPT($G$2:$G$61,$A$2:$A$61)+SLOPE($G$2:$G$61,$A$2:$A$61)*A38 -> 12.064314 | S38: =G38-R38 -> -9.6113141 | T38: =ABS(S38) -> 9.6113141 | U38: =IFERROR((S38-AVERAGE($S$2:$S$61))/stdev.s($S$2:$S$61),"") -> -0.85741181 | V38: =IF(ABS(U38)>=Source!$B$10,"Anomaly","") | W38: =IF(A38<=12,"",G38-INDEX($G:$G,ROW()-12)) -> 0.937 | X38: =IF(C38=2019,"Baseline",IF(C38<=2021,"COVID shock",IF(C38=2022,"Reopening","Recovery"))) -> Reopening | Y38: =IFERROR(ABS(S38/G38),"") -> 3.9181876
A39: 38 | B39: 44593 | C39: =YEAR(B39) -> 2022 | D39: =MONTH(B39) -> 2 | E39: =TEXT(B39,"mmm") -> Feb | F39: Asia and the Pacific | G39: 2.56 | H39: =IFERROR(LN(G39),"") -> 0.94000726 | I39: =IF(A39=1,"",G39-G38) -> 0.107 | J39: =IFERROR(G39/INDEX($G:$G,MATCH(DATE(C39-1,D39,1),$B:$B,0))-1,"") -> 0.68865435 | K39: =AVERAGE(G37:G39) -> 2.951 | L39: =AVERAGE(G34:G39) -> 2.7048333 | M39: =AVERAGE(G28:G39) -> 2.3713333 | N39: =AVERAGE(G34:G45) -> 4.588 | O39: =IFERROR(G39/G3,"") -> 0.084304815 | P39: =AVERAGEIFS($G:$G,$D:$D,D39,$C:$C,"<="&Source!$B$8)-AVERAGEIFS($G:$G,$C:$C,"<="&Source!$B$8) -> 0.25428333 | Q39: =G39-P39 -> 2.3057167 | R39: =INTERCEPT($G$2:$G$61,$A$2:$A$61)+SLOPE($G$2:$G$61,$A$2:$A$61)*A39 -> 11.92336 | S39: =G39-R39 -> -9.3633599 | T39: =ABS(S39) -> 9.3633599 | U39: =IFERROR((S39-AVERAGE($S$2:$S$61))/stdev.s($S$2:$S$61),"") -> -0.83529216 | V39: =IF(ABS(U39)>=Source!$B$10,"Anomaly","") | W39: =IF(A39<=12,"",G39-INDEX($G:$G,ROW()-12)) -> 1.044 | X39: =IF(C39=2019,"Baseline",IF(C39<=2021,"COVID shock",IF(C39=2022,"Reopening","Recovery"))) -> Reopening | Y39: =IFERROR(ABS(S39/G39),"") -> 3.6575625
A40: 39 | B40: 44621 | C40: =YEAR(B40) -> 2022 | D40: =MONTH(B40) -> 3 | E40: =TEXT(B40,"mmm") -> Mar | F40: Asia and the Pacific | G40: 2.987 | H40: =IFERROR(LN(G40),"") -> 1.0942695 | I40: =IF(A40=1,"",G40-G39) -> 0.427 | J40: =IFERROR(G40/INDEX($G:$G,MATCH(DATE(C40-1,D40,1),$B:$B,0))-1,"") -> 0.73864959 | K40: =AVERAGE(G38:G40) -> 2.6666667 | L40: =AVERAGE(G35:G40) -> 2.8658333 | M40: =AVERAGE(G29:G40) -> 2.4770833 | N40: =AVERAGE(G35:G46) -> 5.21075 | O40: =IFERROR(G40/G4,"") -> 0.093387525 | P40: =AVERAGEIFS($G:$G,$D:$D,D40,$C:$C,"<="&Source!$B$8)-AVERAGEIFS($G:$G,$C:$C,"<="&Source!$B$8) -> -1.3653167 | Q40: =G40-P40 -> 4.3523167 | R40: =INTERCEPT($G$2:$G$61,$A$2:$A$61)+SLOPE($G$2:$G$61,$A$2:$A$61)*A40 -> 11.782406 | S40: =G40-R40 -> -8.7954056 | T40: =ABS(S40) -> 8.7954056 | U40: =IFERROR((S40-AVERAGE($S$2:$S$61))/stdev.s($S$2:$S$61),"") -> -0.78462577 | V40: =IF(ABS(U40)>=Source!$B$10,"Anomaly","") | W40: =IF(A40<=12,"",G40-INDEX($G:$G,ROW()-12)) -> 1.269 | X40: =IF(C40=2019,"Baseline",IF(C40<=2021,"COVID shock",IF(C40=2022,"Reopening","Recovery"))) -> Reopening | Y40: =IFERROR(ABS(S40/G40),"") -> 2.9445617
...

Sheet Annual
A1: Annual summary
A3: Year | B3: Months available | C3: Total arrivals, mln | D3: Average monthly, mln | E3: Index to 2019 | F3: YoY change | G3: Min monthly, mln | H3: Max monthly, mln | I3: Completeness
A4: 2019 | B4: =COUNTIFS(Data!$C:$C,A4) -> 12 | C4: =SUMIFS(Data!$G:$G,Data!$C:$C,A4) -> 362.671 | D4: =IFERROR(C4/B4,"") -> 30.222583 | E4: =IFERROR(C4/INDEX($C:$C,MATCH(Source!$B$9,$A:$A,0)),"") -> 1 | F4: =IFERROR(C4/C3-1,"") | G4: =IFERROR(minifs(Data!$G:$G,Data!$C:$C,A4),"") | H4: =IFERROR(maxifs(Data!$G:$G,Data!$C:$C,A4),"") -> 31.985 | I4: =IF(B4=12,"Full year","Partial year") -> Full year
A5: 2020 | B5: =COUNTIFS(Data!$C:$C,A5) -> 12 | C5: =SUMIFS(Data!$G:$G,Data!$C:$C,A5) -> 59.114 | D5: =IFERROR(C5/B5,"") -> 4.9261667 | E5: =IFERROR(C5/INDEX($C:$C,MATCH(Source!$B$9,$A:$A,0)),"") -> 0.16299621 | F5: =IFERROR(C5/C4-1,"") -> -0.83700379 | G5: =IFERROR(minifs(Data!$G:$G,Data!$C:$C,A5),"") | H5: =IFERROR(maxifs(Data!$G:$G,Data!$C:$C,A5),"") -> 28.512 | I5: =IF(B5=12,"Full year","Partial year") -> Full year
A6: 2021 | B6: =COUNTIFS(Data!$C:$C,A6) -> 12 | C6: =SUMIFS(Data!$G:$G,Data!$C:$C,A6) -> 26.475 | D6: =IFERROR(C6/B6,"") -> 2.20625 | E6: =IFERROR(C6/INDEX($C:$C,MATCH(Source!$B$9,$A:$A,0)),"") -> 0.073000047 | F6: =IFERROR(C6/C5-1,"") -> -0.55213655 | G6: =IFERROR(minifs(Data!$G:$G,Data!$C:$C,A6),"") | H6: =IFERROR(maxifs(Data!$G:$G,Data!$C:$C,A6),"") -> 3.84 | I6: =IF(B6=12,"Full year","Partial year") -> Full year
A7: 2022 | B7: =COUNTIFS(Data!$C:$C,A7) -> 12 | C7: =SUMIFS(Data!$G:$G,Data!$C:$C,A7) -> 93.334 | D7: =IFERROR(C7/B7,"") -> 7.7778333 | E7: =IFERROR(C7/INDEX($C:$C,MATCH(Source!$B$9,$A:$A,0)),"") -> 0.2573517 | F7: =IFERROR(C7/C6-1,"") -> 2.5253636 | G7: =IFERROR(minifs(Data!$G:$G,Data!$C:$C,A7),"") | H7: =IFERROR(maxifs(Data!$G:$G,Data!$C:$C,A7),"") -> 16 | I7: =IF(B7=12,"Full year","Partial year") -> Full year
A8: 2023 | B8: =COUNTIFS(Data!$C:$C,A8) -> 12 | C8: =SUMIFS(Data!$G:$G,Data!$C:$C,A8) -> 237.237 | D8: =IFERROR(C8/B8,"") -> 19.76975 | E8: =IFERROR(C8/INDEX($C:$C,MATCH(Source!$B$9,$A:$A,0)),"") -> 0.65413832 | F8: =IFERROR(C8/C7-1,"") -> 1.5418068 | G8: =IFERROR(minifs(Data!$G:$G,Data!$C:$C,A8),"") | H8: =IFERROR(maxifs(Data!$G:$G,Data!$C:$C,A8),"") -> 25.723 | I8: =IF(B8=12,"Full year","Partial year") -> Full year
A9: 2024 | B9: =COUNTIFS(Data!$C:$C,A9) -> 3 | C9: =SUMIFS(Data!$G:$G,Data!$C:$C,A9) -> 76.333 | D9: =IFERROR(C9/B9,"") -> 25.444333 | E9: =IFERROR(C9/INDEX($C:$C,MATCH(Source!$B$9,$A:$A,0)),"") -> 0.21047451 | F9: =IFERROR(C9/C8-1,"") -> -0.67824159 | G9: =IFERROR(minifs(Data!$G:$G,Data!$C:$C,A9),"") | H9: =IFERROR(maxifs(Data!$G:$G,Data!$C:$C,A9),"") -> 26.1 | I9: =IF(B9=12,"Full year","Partial year") -> Partial year

Sheet Seasonality
A1: Seasonality profile by month
A3: Month | B3: Month name | C3: 2019 baseline, mln | D3: 2023, mln | E3: 2024 available, mln | F3: Average 2019-2023, mln | G3: Share 2019 | H3: Share 2023 | I3: Share change, p.p. | J3: Additive seasonal factor | K3: 2023 rank
A4: 1 | B4: Jan | C4: =SUMIFS(Data!$G:$G,Data!$C:$C,Source!$B$9,Data!$D:$D,A4) -> 30.872 | D4: =SUMIFS(Data!$G:$G,Data!$C:$C,2023,Data!$D:$D,A4) -> 14.57 | E4: =IF(SUMIFS(Data!$G:$G,Data!$C:$C,2024,Data!$D:$D,A4)=0,"",SUMIFS(Data!$G:$G,Data!$C:$C,2024,Data!$D:$D,A4)) -> 24.543 | F4: =AVERAGEIFS(Data!$G:$G,Data!$D:$D,A4,Data!$C:$C,">="&Source!$B$9,Data!$C:$C,"<="&Source!$B$8) -> 15.5846 | G4: =C4/SUM($C$4:$C$15) -> 0.085123983 | H4: =D4/SUM($D$4:$D$15) -> 0.061415378 | I4: =(H4-G4)*100 -> -2.3708605 | J4: =F4-AVERAGE($F$4:$F$15) -> 2.6040833 | K4: =rank.eq(D4,$D$4:$D$15,0) -> 12
A5: 2 | B5: Feb | C5: =SUMIFS(Data!$G:$G,Data!$C:$C,Source!$B$9,Data!$D:$D,A5) -> 30.366 | D5: =SUMIFS(Data!$G:$G,Data!$C:$C,2023,Data!$D:$D,A5) -> 15.575 | E5: =IF(SUMIFS(Data!$G:$G,Data!$C:$C,2024,Data!$D:$D,A5)=0,"",SUMIFS(Data!$G:$G,Data!$C:$C,2024,Data!$D:$D,A5)) -> 25.69 | F5: =AVERAGEIFS(Data!$G:$G,Data!$D:$D,A5,Data!$C:$C,">="&Source!$B$9,Data!$C:$C,"<="&Source!$B$8) -> 13.2348 | G5: =C5/SUM($C$4:$C$15) -> 0.083728779 | H5: =D5/SUM($D$4:$D$15) -> 0.065651648 | I5: =(H5-G5)*100 -> -1.8077131 | J5: =F5-AVERAGE($F$4:$F$15) -> 0.25428333 | K5: =rank.eq(D5,$D$4:$D$15,0) -> 11
A6: 3 | B6: Mar | C6: =SUMIFS(Data!$G:$G,Data!$C:$C,Source!$B$9,Data!$D:$D,A6) -> 31.985 | D6: =SUMIFS(Data!$G:$G,Data!$C:$C,2023,Data!$D:$D,A6) -> 17.584 | E6: =IF(SUMIFS(Data!$G:$G,Data!$C:$C,2024,Data!$D:$D,A6)=0,"",SUMIFS(Data!$G:$G,Data!$C:$C,2024,Data!$D:$D,A6)) -> 26.1 | F6: =AVERAGEIFS(Data!$G:$G,Data!$D:$D,A6,Data!$C:$C,">="&Source!$B$9,Data!$C:$C,"<="&Source!$B$8) -> 11.6152 | G6: =C6/SUM($C$4:$C$15) -> 0.08819288 | H6: =D6/SUM($D$4:$D$15) -> 0.074119973 | I6: =(H6-G6)*100 -> -1.4072907 | J6: =F6-AVERAGE($F$4:$F$15) -> -1.3653167 | K6: =rank.eq(D6,$D$4:$D$15,0) -> 10
A7: 4 | B7: Apr | C7: =SUMIFS(Data!$G:$G,Data!$C:$C,Source!$B$9,Data!$D:$D,A7) -> 31.581 | D7: =SUMIFS(Data!$G:$G,Data!$C:$C,2023,Data!$D:$D,A7) -> 18.087 | E7: =IF(SUMIFS(Data!$G:$G,Data!$C:$C,2024,Data!$D:$D,A7)=0,"",SUMIFS(Data!$G:$G,Data!$C:$C,2024,Data!$D:$D,A7)) | F7: =AVERAGEIFS(Data!$G:$G,Data!$D:$D,A7,Data!$C:$C,">="&Source!$B$9,Data!$C:$C,"<="&Source!$B$8) -> 11.3812 | G7: =C7/SUM($C$4:$C$15) -> 0.087078923 | H7: =D7/SUM($D$4:$D$15) -> 0.076240215 | I7: =(H7-G7)*100 -> -1.0838707 | J7: =F7-AVERAGE($F$4:$F$15) -> -1.5993167 | K7: =rank.eq(D7,$D$4:$D$15,0) -> 8
A8: 5 | B8: May | C8: =SUMIFS(Data!$G:$G,Data!$C:$C,Source!$B$9,Data!$D:$D,A8) -> 29.354 | D8: =SUMIFS(Data!$G:$G,Data!$C:$C,2023,Data!$D:$D,A8) -> 18.087 | E8: =IF(SUMIFS(Data!$G:$G,Data!$C:$C,2024,Data!$D:$D,A8)=0,"",SUMIFS(Data!$G:$G,Data!$C:$C,2024,Data!$D:$D,A8)) | F8: =AVERAGEIFS(Data!$G:$G,Data!$D:$D,A8,Data!$C:$C,">="&Source!$B$9,Data!$C:$C,"<="&Source!$B$8) -> 11.2344 | G8: =C8/SUM($C$4:$C$15) -> 0.080938371 | H8: =D8/SUM($D$4:$D$15) -> 0.076240215 | I8: =(H8-G8)*100 -> -0.46981557 | J8: =F8-AVERAGE($F$4:$F$15) -> -1.7461167 | K8: =rank.eq(D8,$D$4:$D$15,0) -> 8
A9: 6 | B9: Jun | C9: =SUMIFS(Data!$G:$G,Data!$C:$C,Source!$B$9,Data!$D:$D,A9) -> 29.556 | D9: =SUMIFS(Data!$G:$G,Data!$C:$C,2023,Data!$D:$D,A9) -> 19.594 | E9: =IF(SUMIFS(Data!$G:$G,Data!$C:$C,2024,Data!$D:$D,A9)=0,"",SUMIFS(Data!$G:$G,Data!$C:$C,2024,Data!$D:$D,A9)) | F9: =AVERAGEIFS(Data!$G:$G,Data!$D:$D,A9,Data!$C:$C,">="&Source!$B$9,Data!$C:$C,"<="&Source!$B$8) -> 11.8748 | G9: =C9/SUM($C$4:$C$15) -> 0.08149535 | H9: =D9/SUM($D$4:$D$15) -> 0.082592513 | I9: =(H9-G9)*100 -> 0.10971632 | J9: =F9-AVERAGE($F$4:$F$15) -> -1.1057167 | K9: =rank.eq(D9,$D$4:$D$15,0) -> 7
A10: 7 | B10: Jul | C10: =SUMIFS(Data!$G:$G,Data!$C:$C,Source!$B$9,Data!$D:$D,A10) -> 30.872 | D10: =SUMIFS(Data!$G:$G,Data!$C:$C,2023,Data!$D:$D,A10) -> 21.603 | E10: =IF(SUMIFS(Data!$G:$G,Data!$C:$C,2024,Data!$D:$D,A10)=0,"",SUMIFS(Data!$G:$G,Data!$C:$C,2024,Data!$D:$D,A10)) | F10: =AVERAGEIFS(Data!$G:$G,Data!$D:$D,A10,Data!$C:$C,">="&Source!$B$9,Data!$C:$C,"<="&Source!$B$8) -> 13.101 | G10: =C10/SUM($C$4:$C$15) -> 0.085123983 | H10: =D10/SUM($D$4:$D$15) -> 0.091060838 | I10: =(H10-G10)*100 -> 0.5936855 | J10: =F10-AVERAGE($F$4:$F$15) -> 0.12048333 | K10: =rank.eq(D10,$D$4:$D$15,0) -> 5
A11: 8 | B11: Aug | C11: =SUMIFS(Data!$G:$G,Data!$C:$C,Source!$B$9,Data!$D:$D,A11) -> 30.366 | D11: =SUMIFS(Data!$G:$G,Data!$C:$C,2023,Data!$D:$D,A11) -> 22.106 | E11: =IF(SUMIFS(Data!$G:$G,Data!$C:$C,2024,Data!$D:$D,A11)=0,"",SUMIFS(Data!$G:$G,Data!$C:$C,2024,Data!$D:$D,A11)) | F11: =AVERAGEIFS(Data!$G:$G,Data!$D:$D,A11,Data!$C:$C,">="&Source!$B$9,Data!$C:$C,"<="&Source!$B$8) -> 13.25 | G11: =C11/SUM($C$4:$C$15) -> 0.083728779 | H11: =D11/SUM($D$4:$D$15) -> 0.093181081 | I11: =(H11-G11)*100 -> 0.94523015 | J11: =F11-AVERAGE($F$4:$F$15) -> 0.26948333 | K11: =rank.eq(D11,$D$4:$D$15,0) -> 3
A12: 9 | B12: Sep | C12: =SUMIFS(Data!$G:$G,Data!$C:$C,Source!$B$9,Data!$D:$D,A12) -> 27.127 | D12: =SUMIFS(Data!$G:$G,Data!$C:$C,2023,Data!$D:$D,A12) -> 20.297 | E12: =IF(SUMIFS(Data!$G:$G,Data!$C:$C,2024,Data!$D:$D,A12)=0,"",SUMIFS(Data!$G:$G,Data!$C:$C,2024,Data!$D:$D,A12)) | F12: =AVERAGEIFS(Data!$G:$G,Data!$D:$D,A12,Data!$C:$C,">="&Source!$B$9,Data!$C:$C,"<="&Source!$B$8) -> 12.168 | G12: =C12/SUM($C$4:$C$15) -> 0.07479782 | H12: =D12/SUM($D$4:$D$15) -> 0.085555794 | I12: =(H12-G12)*100 -> 1.0757975 | J12: =F12-AVERAGE($F$4:$F$15) -> -0.81251667 | K12: =rank.eq(D12,$D$4:$D$15,0) -> 6
A13: 10 | B13: Oct | C13: =SUMIFS(Data!$G:$G,Data!$C:$C,Source!$B$9,Data!$D:$D,A13) -> 29.354 | D13: =SUMIFS(Data!$G:$G,Data!$C:$C,2023,Data!$D:$D,A13) -> 21.704 | E13: =IF(SUMIFS(Data!$G:$G,Data!$C:$C,2024,Data!$D:$D,A13)=0,"",SUMIFS(Data!$G:$G,Data!$C:$C,2024,Data!$D:$D,A13)) | F13: =AVERAGEIFS(Data!$G:$G,Data!$D:$D,A13,Data!$C:$C,">="&Source!$B$9,Data!$C:$C,"<="&Source!$B$8) -> 13.0684 | G13: =C13/SUM($C$4:$C$15) -> 0.080938371 | H13: =D13/SUM($D$4:$D$15) -> 0.091486572 | I13: =(H13-G13)*100 -> 1.0548201 | J13: =F13-AVERAGE($F$4:$F$15) -> 0.087883333 | K13: =rank.eq(D13,$D$4:$D$15,0) -> 4
A14: 11 | B14: Nov | C14: =SUMIFS(Data!$G:$G,Data!$C:$C,Source!$B$9,Data!$D:$D,A14) -> 29.556 | D14: =SUMIFS(Data!$G:$G,Data!$C:$C,2023,Data!$D:$D,A14) -> 22.307 | E14: =IF(SUMIFS(Data!$G:$G,Data!$C:$C,2024,Data!$D:$D,A14)=0,"",SUMIFS(Data!$G:$G,Data!$C:$C,2024,Data!$D:$D,A14)) | F14: =AVERAGEIFS(Data!$G:$G,Data!$D:$D,A14,Data!$C:$C,">="&Source!$B$9,Data!$C:$C,"<="&Source!$B$8) -> 13.6528 | G14: =C14/SUM($C$4:$C$15) -> 0.08149535 | H14: =D14/SUM($D$4:$D$15) -> 0.094028335 | I14: =(H14-G14)*100 -> 1.2532985 | J14: =F14-AVERAGE($F$4:$F$15) -> 0.67228333 | K14: =rank.eq(D14,$D$4:$D$15,0) -> 2
A15: 12 | B15: Dec | C15: =SUMIFS(Data!$G:$G,Data!$C:$C,Source!$B$9,Data!$D:$D,A15) -> 31.682 | D15: =SUMIFS(Data!$G:$G,Data!$C:$C,2023,Data!$D:$D,A15) -> 25.723 | E15: =IF(SUMIFS(Data!$G:$G,Data!$C:$C,2024,Data!$D:$D,A15)=0,"",SUMIFS(Data!$G:$G,Data!$C:$C,2024,Data!$D:$D,A15)) | F15: =AVERAGEIFS(Data!$G:$G,Data!$D:$D,A15,Data!$C:$C,">="&Source!$B$9,Data!$C:$C,"<="&Source!$B$8) -> 15.601 | G15: =C15/SUM($C$4:$C$15) -> 0.087357412 | H15: =D15/SUM($D$4:$D$15) -> 0.10842744 | I15: =(H15-G15)*100 -> 2.1070025 | J15: =F15-AVERAGE($F$4:$F$15) -> 2.6204833 | K15: =rank.eq(D15,$D$4:$D$15,0) -> 1

Sheet ACF
A1: Autocorrelation and stationarity checks
A3: Lag | B3: ACF raw series | C3: ACF first difference | D3: ACF seasonal difference | E3: +/- significance band | F3: Technical note | H3: Check | I3: Formula result | J3: Meaning
A4: 0 | B4: =1 -> 1 | C4: =1 -> 1 | D4: =1 -> 1 | E4: =1.96/SQRT(COUNT(Data!$G$2:$G$61)) -> 0.25303491 | F4: ="Lag 0 baseline" -> Lag 0 baseline | H4: Raw lag-1 ACF | I4: =B5 -> 0.9723408 | J4: High value means trend/persistence
A5: 1 | B5: =CORREL(Data!$G$2:$G$60,Data!$G$3:$G$61) -> 0.9723408 | C5: =CORREL(Data!$I$3:$I$60,Data!$I$4:$I$61) -> 0.56078478 | D5: =CORREL(Data!$W$14:$W$60,Data!$W$15:$W$61) -> 0.96717693 | E5: =1.96/SQRT(COUNT(Data!$G$2:$G$61)) -> 0.25303491 | F5: =IF(ABS(B5)>E5,"Outside band","Within band") -> Outside band | H5: First-difference lag-1 ACF | I5: =C5 -> 0.56078478 | J5: Lower value means differencing reduces persistence
A6: 2 | B6: =CORREL(Data!$G$2:$G$59,Data!$G$4:$G$61) -> 0.91273026 | C6: =CORREL(Data!$I$3:$I$59,Data!$I$5:$I$61) -> 0.11892226 | D6: =CORREL(Data!$W$14:$W$59,Data!$W$16:$W$61) -> 0.90154202 | E6: =1.96/SQRT(COUNT(Data!$G$2:$G$61)) -> 0.25303491 | F6: =IF(ABS(B6)>E6,"Outside band","Within band") -> Outside band | H6: Seasonal lag-12 ACF | I6: =B16 -> -0.11755962 | J6: Large value signals yearly seasonality
A7: 3 | B7: =CORREL(Data!$G$2:$G$58,Data!$G$5:$G$61) -> 0.84306761 | C7: =CORREL(Data!$I$3:$I$58,Data!$I$6:$I$61) -> -0.059200731 | D7: =CORREL(Data!$W$14:$W$58,Data!$W$17:$W$61) -> 0.85159347 | E7: =1.96/SQRT(COUNT(Data!$G$2:$G$61)) -> 0.25303491 | F7: =IF(ABS(B7)>E7,"Outside band","Within band") -> Outside band | H7: Recommended transformation | I7: =IF(ABS(C5)<ABS(B5),"First difference improves stationarity","Raw series remains highly persistent") -> First difference improves stationarity | J7: Use first and seasonal differences for stationarity checks
A8: 4 | B8: =CORREL(Data!$G$2:$G$57,Data!$G$6:$G$61) -> 0.77401508 | C8: =CORREL(Data!$I$3:$I$57,Data!$I$7:$I$61) -> -0.0060078557 | D8: =CORREL(Data!$W$14:$W$57,Data!$W$18:$W$61) -> 0.81202667 | E8: =1.96/SQRT(COUNT(Data!$G$2:$G$61)) -> 0.25303491 | F8: =IF(ABS(B8)>E8,"Outside band","Within band") -> Outside band | H8: Main complete sample | I8: =COUNT(Data!$G$2:$G$61) -> 60 | J8: 2019-2023 monthly observations
A9: 5 | B9: =CORREL(Data!$G$2:$G$56,Data!$G$7:$G$61) -> 0.69985089 | C9: =CORREL(Data!$I$3:$I$56,Data!$I$8:$I$61) -> 0.048393767 | D9: =CORREL(Data!$W$14:$W$56,Data!$W$19:$W$61) -> 0.77018624 | E9: =1.96/SQRT(COUNT(Data!$G$2:$G$61)) -> 0.25303491 | F9: =IF(ABS(B9)>E9,"Outside band","Within band") -> Outside band
A10: 6 | B10: =CORREL(Data!$G$2:$G$55,Data!$G$8:$G$61) -> 0.61803223 | C10: =CORREL(Data!$I$3:$I$55,Data!$I$9:$I$61) -> 0.091653076 | D10: =CORREL(Data!$W$14:$W$55,Data!$W$20:$W$61) -> 0.73253207 | E10: =1.96/SQRT(COUNT(Data!$G$2:$G$61)) -> 0.25303491 | F10: =IF(ABS(B10)>E10,"Outside band","Within band") -> Outside band
A11: 7 | B11: =CORREL(Data!$G$2:$G$54,Data!$G$9:$G$61) -> 0.52605146 | C11: =CORREL(Data!$I$3:$I$54,Data!$I$10:$I$61) -> 0.091766492 | D11: =CORREL(Data!$W$14:$W$54,Data!$W$21:$W$61) -> 0.69984766 | E11: =1.96/SQRT(COUNT(Data!$G$2:$G$61)) -> 0.25303491 | F11: =IF(ABS(B11)>E11,"Outside band","Within band") -> Outside band
A12: 8 | B12: =CORREL(Data!$G$2:$G$53,Data!$G$10:$G$61) -> 0.42397563 | C12: =CORREL(Data!$I$3:$I$53,Data!$I$11:$I$61) -> 0.08099464 | D12: =CORREL(Data!$W$14:$W$53,Data!$W$22:$W$61) -> 0.65734885 | E12: =1.96/SQRT(COUNT(Data!$G$2:$G$61)) -> 0.25303491 | F12: =IF(ABS(B12)>E12,"Outside band","Within band") -> Outside band
A13: 9 | B13: =CORREL(Data!$G$2:$G$52,Data!$G$11:$G$61) -> 0.31411399 | C13: =CORREL(Data!$I$3:$I$52,Data!$I$12:$I$61) -> 0.087537276 | D13: =CORREL(Data!$W$14:$W$52,Data!$W$23:$W$61) -> 0.59291691 | E13: =1.96/SQRT(COUNT(Data!$G$2:$G$61)) -> 0.25303491 | F13: =IF(ABS(B13)>E13,"Outside band","Within band") -> Outside band
A14: 10 | B14: =CORREL(Data!$G$2:$G$51,Data!$G$12:$G$61) -> 0.18504019 | C14: =CORREL(Data!$I$3:$I$51,Data!$I$13:$I$61) -> 0.055214984 | D14: =CORREL(Data!$W$14:$W$51,Data!$W$24:$W$61) -> 0.52886179 | E14: =1.96/SQRT(COUNT(Data!$G$2:$G$61)) -> 0.25303491 | F14: =IF(ABS(B14)>E14,"Outside band","Within band") -> Within band
A15: 11 | B15: =CORREL(Data!$G$2:$G$50,Data!$G$13:$G$61) -> 0.043655713 | C15: =CORREL(Data!$I$3:$I$50,Data!$I$14:$I$61) -> -0.057499052 | D15: =CORREL(Data!$W$14:$W$50,Data!$W$25:$W$61) -> 0.47140415 | E15: =1.96/SQRT(COUNT(Data!$G$2:$G$61)) -> 0.25303491 | F15: =IF(ABS(B15)>E15,"Outside band","Within band") -> Within band
A16: 12 | B16: =CORREL(Data!$G$2:$G$49,Data!$G$14:$G$61) -> -0.11755962 | C16: =CORREL(Data!$I$3:$I$49,Data!$I$15:$I$61) -> 0.021142271 | D16: =CORREL(Data!$W$14:$W$49,Data!$W$26:$W$61) -> 0.4915382 | E16: =1.96/SQRT(COUNT(Data!$G$2:$G$61)) -> 0.25303491 | F16: =IF(ABS(B16)>E16,"Outside band","Within band") -> Within band
A17: 13 | B17: =CORREL(Data!$G$2:$G$48,Data!$G$15:$G$61) -> -0.29596424 | C17: =CORREL(Data!$I$3:$I$48,Data!$I$16:$I$61) -> 0.064031775 | D17: =CORREL(Data!$W$14:$W$48,Data!$W$27:$W$61) -> 0.64386578 | E17: =1.96/SQRT(COUNT(Data!$G$2:$G$61)) -> 0.25303491 | F17: =IF(ABS(B17)>E17,"Outside band","Within band") -> Outside band
A18: 14 | B18: =CORREL(Data!$G$2:$G$47,Data!$G$16:$G$61) -> -0.40787107 | C18: =CORREL(Data!$I$3:$I$47,Data!$I$17:$I$61) -> 0.085572091 | D18: =CORREL(Data!$W$14:$W$47,Data!$W$28:$W$61) -> 0.81663321 | E18: =1.96/SQRT(COUNT(Data!$G$2:$G$61)) -> 0.25303491 | F18: =IF(ABS(B18)>E18,"Outside band","Within band") -> Outside band
